Workbook
Name Cía: '[1]Gráfico Diario x Marca'!$A$30:$A$32
Name Marca: '[1]Gráfico R Vs C'!$A$18:$A$38
Name Marca2: '[1]Gráfico Diario x Marca'!$A$1:$A$21
Name SKU: '[1]Gráfico R Vs C'!$A$40:$A$116
Name UB: '[1]Gráfico Diario x Marca'!$A$27:$A$28

Sheet Clientes
A1: Número de cliente | B1: Nombre de cliente de maestro de cliente | C1: Nombre corto | D1: SUB-CATEGORIA | E1: Estado o provincia | F1: RUT | G1: CódigoDirección | H1: AÑO COD | I1: CANAL DE DISTRIBUCIÓN | J1: REGIÓN | K1: SUCRUSAL
A2: J317255208 | B2: ADMINISTRADORA SD 1980, C.A | C2: ADMINT SD 1980 | D2: =+VLOOKUP(A2,Tabla3[],18,0) -> CADENAS - SUPERMERCADOS | E2: =+VLOOKUP(A2,Tabla3[],7,0) -> ARAGUA | F2: 20 | G2: 20001 | I2: POR ASIGNAR | J2: CENTRAL | L2: =+A2 -> J317255208
A3: V170806634 | B3: ALARCON DIAZ ERICK | C3: ALARCON ERICK | D3: =+VLOOKUP(A3,Tabla3[],18,0) -> #N/A | E3: =+VLOOKUP(A3,Tabla3[],7,0) -> #N/A | I3: POR ASIGNAR | J3: 0 | L3: =+A3 -> V170806634
A4: V235652923 | B4: ALEXIS RIVAS | C4: ALEXIS RIVAS | D4: =+VLOOKUP(A4,Tabla3[],18,0) -> #N/A | E4: =+VLOOKUP(A4,Tabla3[],7,0) -> #N/A | I4: POR ASIGNAR | J4: 0 | L4: =+A4 -> V235652923
A5: J402835604 | B5: ALIADOS COMERCIALES, C.A. | C5: ALIADOS COMERC | D5: =+VLOOKUP(A5,Tabla3[],18,0) -> DISTRIBUIDOR | E5: =+VLOOKUP(A5,Tabla3[],7,0) -> FALCON | F5: 65 | G5: 65001 | I5: POR ASIGNAR | J5: FALCON | L5: =+A5 -> J402835604
A6: J402802218 | B6: ALIANZA DISTRIBUIDORA C.A | C6: 30 SAN JUAN | D6: =+VLOOKUP(A6,Tabla3[],18,0) -> DISTRIBUIDOR | E6: =+VLOOKUP(A6,Tabla3[],7,0) -> ZULIA | F6: 64 | G6: 64001 | I6: DISTRIBUIDOR | J6: 0 | L6: =+A6 -> J402802218
A7: J312492031 | B7: AMIFARMACIA, C.A. | C7: 65 LOCATEL | D7: =+VLOOKUP(A7,Tabla3[],18,0) -> CADENAS - FARMACIAS | E7: =+VLOOKUP(A7,Tabla3[],7,0) -> CARABOBO | F7: 11 | G7: 11001 | I7: FARMACIA | J7: CENTRAL | L7: =+A7 -> J312492031
A8: V195648545 | B8: ANDERSON SOLAR | C8: ANDERSON SOLAR | D8: =+VLOOKUP(A8,Tabla3[],18,0) -> #N/A | E8: =+VLOOKUP(A8,Tabla3[],7,0) -> #N/A | I8: EMPLEADOS | J8: 0 | L8: =+A8 -> V195648545
A9: V206532960 | B9: ANGI AZZOLLINI | C9: ANGI AZZOLLINI | D9: =+VLOOKUP(A9,Tabla3[],18,0) -> #N/A | E9: =+VLOOKUP(A9,Tabla3[],7,0) -> #N/A | I9: EMPLEADOS | J9: 0 | L9: =+A9 -> V206532960
A10: J298008040 | B10: ARCO SUMINISTROS, C.A. | C10: ARCO SUMINISTRO | D10: =+VLOOKUP(A10,Tabla3[],18,0) -> DISTRIBUIDOR | E10: =+VLOOKUP(A10,Tabla3[],7,0) -> MERIDA | F10: 63 | G10: 63037 | I10: POR ASIGNAR | J10: 0 | L10: =+A10 -> J298008040
A11: J303032338 | B11: ARS PUBLICIDAD VENEZUELA, S.A. | C11: ARS PUBLICIDAD | D11: =+VLOOKUP(A11,Tabla3[],18,0) -> #N/A | E11: =+VLOOKUP(A11,Tabla3[],7,0) -> #N/A | F11: 51 | G11: 51021 | I11: POR ASIGNAR | J11: 0 | L11: =+A11 -> J303032338
A12: J308597724 | B12: ASMEDICAL, C.A. | C12: ASMEDICAL | D12: =+VLOOKUP(A12,Tabla3[],18,0) -> #N/A | E12: =+VLOOKUP(A12,Tabla3[],7,0) -> #N/A | I12: POR ASIGNAR | J12: 0 | L12: =+A12 -> J308597724
A13: J294462847 | B13: ASOC CIVIL CAJA DE AHORRO DEL EJERC BOLIVARIANO | C13: EJERC BOLIVARIA | D13: =+VLOOKUP(A13,Tabla3[],18,0) -> INSTITUCIONAL | E13: =+VLOOKUP(A13,Tabla3[],7,0) -> DISTRITO CAPITAL | F13: 10 | I13: POR ASIGNAR | J13: 0 | L13: =+A13 -> J294462847
A14: J302517079 | B14: ASOCIACION CIVIL HOGAR BAMBI VENEZUELA | C14: HOGAR BAMBI | D14: =+VLOOKUP(A14,Tabla3[],18,0) -> #N/A | E14: =+VLOOKUP(A14,Tabla3[],7,0) -> #N/A | I14: POR ASIGNAR | J14: 0 | L14: =+A14 -> J302517079
A15: J404498923 | B15: ASOCOMPRA ASOCIACIÓN DE COMPRADORES, A.C. | C15: ASOCOMPRA | D15: =+VLOOKUP(A15,Tabla3[],18,0) -> INSTITUCIONAL | E15: =+VLOOKUP(A15,Tabla3[],7,0) -> MIRANDA | F15: 95 | G15: 95001 | I15: POR ASIGNAR | J15: CAPITAL | L15: =+A15 -> J404498923
A16: J075245113 | B16: AUTO MERCADO SAN DIEGO, C.A. | C16: 37 SAN DIEGO | D16: =+VLOOKUP(A16,Tabla3[],18,0) -> CADENAS - SUPERMERCADOS | E16: =+VLOOKUP(A16,Tabla3[],7,0) -> ARAGUA | F16: 12 | G16: 12025 | I16: AUTOMERCADO | J16: CENTRAL | L16: =+A16 -> J075245113
A17: J413118440 | B17: AUTOMERCADO CHINATOWN SAN JUAN 2020, C.A | C17: CHINAT SAN JUAN | D17: =+VLOOKUP(A17,Tabla3[],18,0) -> MAYORISTAS | E17: =+VLOOKUP(A17,Tabla3[],7,0) -> DISTRITO CAPITAL | F17: 58 | G17: 54018 | I17: AUTOMERCADO | J17: CAPITAL | L17: =+A17 -> J413118440
A18: J304983905 | B18: AUTOMERCADO COSMO FRONTERA, C.A | C18: AUT COSMO FRONT | D18: =+VLOOKUP(A18,Tabla3[],18,0) -> SUPERMERCADOS INDEPENDIENTES | E18: =+VLOOKUP(A18,Tabla3[],7,0) -> TACHIRA | F18: 63 | G18: 63029 | I18: AUTOMERCADO | J18: 0 | L18: =+A18 -> J304983905
A19: J000859400 | B19: AUTOMERCADO EL PATIO LOS PALOS GRANDES | C19: 70 EL PATIO | D19: =+VLOOKUP(A19,Tabla3[],18,0) -> CADENAS - SUPERMERCADOS | E19: =+VLOOKUP(A19,Tabla3[],7,0) -> MIRANDA | F19: 57 | G19: 50001 | I19: AUTOMERCADO | J19: CAPITAL | L19: =+A19 -> J000859400
A20: J003720224 | B20: AUTOMERCADO LA MURALLA C.A. | C20: AUT LA MURALLA | D20: =+VLOOKUP(A20,Tabla3[],18,0) -> SUPERMERCADOS INDEPENDIENTES | E20: =+VLOOKUP(A20,Tabla3[],7,0) -> MIRANDA | F20: 57 | G20: 50026 | H20: 2019 | I20: AUTOMERCADO | J20: CAPITAL | L20: =+A20 -> J003720224
A21: J000811601 | B21: AUTOMERCADO LUZ C.A. | C21: AUTOMERCADO LUZ | D21: =+VLOOKUP(A21,Tabla3[],18,0) -> CADENAS - SUPERMERCADOS | E21: =+VLOOKUP(A21,Tabla3[],7,0) -> MIRANDA | F21: 50 | G21: 50002 | I21: AUTOMERCADO | J21: CAPITAL | L21: =+A21 -> J000811601
A22: J000537585 | B22: AUTOMERCADO SAN LORENZO C.A. | C22: AUT SAN LORENZO | D22: =+VLOOKUP(A22,Tabla3[],18,0) -> SUPERMERCADOS INDEPENDIENTES | E22: =+VLOOKUP(A22,Tabla3[],7,0) -> MIRANDA | F22: 57 | G22: 50003 | I22: AUTOMERCADO | J22: CAPITAL | L22: =+A22 -> J000537585
A23: J002099712 | B23: AUTOMERCADO SANTA ROSA DE LIMA C.A | C23: STA ROSA LIMA | D23: =+VLOOKUP(A23,Tabla3[],18,0) -> SUPERMERCADOS INDEPENDIENTES | E23: =+VLOOKUP(A23,Tabla3[],7,0) -> MIRANDA | F23: 57 | G23: 50004 | I23: AUTOMERCADO | J23: CAPITAL | L23: =+A23 -> J002099712
A24: J314301870 | B24: AUTOMERCADO SUPER EXITO COMPAÑIA ANONIMA | C24: AUT SUPER EXITO | D24: =+VLOOKUP(A24,Tabla3[],18,0) -> #N/A | E24: =+VLOOKUP(A24,Tabla3[],7,0) -> #N/A | I24: AUTOMERCADO | J24: 0 | L24: =+A24 -> J314301870
A25: J298782366 | B25: AUTOMERCADOS FRESCO MARKET AFN C.A. | C25: 66 FRESC.MARKET | D25: =+VLOOKUP(A25,Tabla3[],18,0) -> SUPERMERCADOS INDEPENDIENTES | E25: =+VLOOKUP(A25,Tabla3[],7,0) -> MIRANDA | F25: 10 | G25: 51001 | I25: AUTOMERCADO | J25: 0 | L25: =+A25 -> J298782366
A26: J305113530 | B26: AUTOMERCADOS KLASSE, C.A. | C26: AUT KLASSE | D26: =+VLOOKUP(A26,Tabla3[],18,0) -> SUPERMERCADOS INDEPENDIENTES | E26: =+VLOOKUP(A26,Tabla3[],7,0) -> MIRANDA | F26: 50 | G26: 50005 | I26: AUTOMERCADO | J26: 0 | L26: =+A26 -> J305113530
A27: J306725024 | B27: AUTOMERCADOS PLAZA'S, C.A. | C27: 42 PLAZA | D27: =+VLOOKUP(A27,Tabla3[],18,0) -> CADENAS - SUPERMERCADOS | E27: =+VLOOKUP(A27,Tabla3[],7,0) -> MIRANDA | F27: 10 | G27: 10040 | I27: AUTOMERCADO | J27: CAPITAL | L27: =+A27 -> J306725024
A28: J407238035 | B28: AUTOMERCADOS SUPER REY VALENCIA C,A | C28: AUTOM SUPER REY | D28: =+VLOOKUP(A28,Tabla3[],18,0) -> SUPERMERCADOS INDEPENDIENTES | E28: =+VLOOKUP(A28,Tabla3[],7,0) -> CARABOBO | F28: 20 | G28: 20053 | I28: AUTOMERCADO | J28: CENTRAL | L28: =+A28 -> J407238035
A29: J316324311 | B29: AUTOMERCADOS SUPER REY, C.A | C29: AUTOM SUPER REY | D29: =+VLOOKUP(A29,Tabla3[],18,0) -> SUPERMERCADOS INDEPENDIENTES | E29: =+VLOOKUP(A29,Tabla3[],7,0) -> ARAGUA | F29: 20 | G29: 20022 | I29: AUTOMERCADO | J29: CENTRAL | L29: =+A29 -> J316324311
A30: J310186839 | B30: AUTOSALUD FARMACIA, C.A. | C30: 65 LOCATEL | D30: =+VLOOKUP(A30,Tabla3[],18,0) -> CADENAS - FARMACIAS | E30: =+VLOOKUP(A30,Tabla3[],7,0) -> CARABOBO | F30: 11 | G30: 11002 | I30: AUTOMERCADO | J30: 0 | L30: =+A30 -> J310186839
A31: J316786110 | B31: AVILA PINTURAS, C.A. | C31: AVILA PINTURA | D31: =+VLOOKUP(A31,Tabla3[],18,0) -> INSTITUCIONAL | E31: =+VLOOKUP(A31,Tabla3[],7,0) -> MIRANDA | F31: 95 | G31: 95012 | I31: POR ASIGNAR | J31: 0 | L31: =+A31 -> J316786110
A32: V069096979 | B32: BAENA FERRER ELIZABETH | C32: BAENA ELIZABETH | D32: =+VLOOKUP(A32,Tabla3[],18,0) -> #N/A | E32: =+VLOOKUP(A32,Tabla3[],7,0) -> #N/A | I32: EMPLEADOS | J32: 0 | L32: =+A32 -> V069096979
A33: G200001100 | B33: BANCO CENTRAL DE VENEZUELA | C33: BCO CTRAL VZLA | D33: =+VLOOKUP(A33,Tabla3[],18,0) -> INSTITUCIONAL | E33: =+VLOOKUP(A33,Tabla3[],7,0) -> DISTRITO CAPITAL | F33: 63 | G33: 63032 | I33: POR ASIGNAR | J33: 0 | L33: =+A33 -> G200001100
A34: G200051876 | B34: BANCO DEL TESORO, C.A BANCO UNIVERSAL | C34: BCO TESORO | D34: =+VLOOKUP(A34,Tabla3[],18,0) -> #N/A | E34: =+VLOOKUP(A34,Tabla3[],7,0) -> #N/A | F34: 11 | G34: 11051 | I34: POR ASIGNAR | J34: 0 | L34: =+A34 -> G200051876
A35: J314850890 | B35: BARINTEL FARMACIA, C.A. | C35: 65 LOCATEL | D35: =+VLOOKUP(A35,Tabla3[],18,0) -> CADENAS - FARMACIAS | E35: =+VLOOKUP(A35,Tabla3[],7,0) -> BARINAS | F35: 23 | G35: 23018 | I35: FARMACIA | J35: LLANOS | L35: =+A35 -> J314850890
A36: V134733000 | B36: BARRIOS O VANESSA MILAGROS | C36: BARRIOS VANESSA | D36: =+VLOOKUP(A36,Tabla3[],18,0) -> #N/A | E36: =+VLOOKUP(A36,Tabla3[],7,0) -> #N/A | I36: EMPLEADOS | J36: 0 | L36: =+A36 -> V134733000
A37: J314527363 | B37: BAZAR AVANZA, C.A. | C37: BAZAR AVANZA | D37: =+VLOOKUP(A37,Tabla3[],18,0) -> MAYORISTAS | E37: =+VLOOKUP(A37,Tabla3[],7,0) -> ARAGUA | F37: 60 | G37: 60001 | I37: POR ASIGNAR | J37: CENTRAL | L37: =+A37 -> J314527363
A38: J000723060 | B38: BFC BANCO FONDO COMUN C.A., BANCO UNIVERSAL | C38: BCO BFC | D38: =+VLOOKUP(A38,Tabla3[],18,0) -> #N/A | E38: =+VLOOKUP(A38,Tabla3[],7,0) -> #N/A | F38: 10 | G38: 10033 | I38: POR ASIGNAR | J38: 0 | L38: =+A38 -> J000723060
A39: V193356156 | B39: BIDROGO MACHUCA JORGE LUIS | C39: BIDROGO JORGE | D39: =+VLOOKUP(A39,Tabla3[],18,0) -> #N/A | E39: =+VLOOKUP(A39,Tabla3[],7,0) -> #N/A | I39: EMPLEADOS | J39: 0 | L39: =+A39 -> V193356156
A40: J410939648 | B40: BIG DISTRIBUCIONES, CA | C40: BIG DISTRIB | D40: =+VLOOKUP(A40,Tabla3[],18,0) -> DISTRIBUIDOR | E40: =+VLOOKUP(A40,Tabla3[],7,0) -> ZULIA | F40: 62 | H40: 2019 | I40: DISTRIBUIDOR | J40: 0 | L40: =+A40 -> J410939648
...

Sheet CLIENTES NUEVA ID ZONA
A1: Número de cliente | B1: Nombre de cliente de maestro de cliente | C1: ID ASESOR ANTERIOR | D1: NUEVA RUTA | E1: NUEVO ASESOR | F1: NUEVO GERENTE | G1: Estado o provincia | H1: REGIÓN | I1: NOMBRE CORTO | J1: ZONA COBRANZA | K1: ASESOR COBRANZA | L1: POTENCIAL ZONA | M1: CONVENIO | N1: Clase de cliente | O1: Días crédito | P1: FRECUENCIA | Q1: APTO | R1: Desc Clase de Cliente | S1: Dirección 1 | T1: Dirección 2 | U1: Ciudad | V1: Observaciones
A2: J413213850 | B2: 3J DISTRIBUCIONES, C.A. | C2: 98 | D2: 98 | E2: =VLOOKUP($D2,'ESTRUCTURA P&B - LP'!$A$1:$F$31,5,0) -> INACTIVO | F2: =VLOOKUP($D2,'ESTRUCTURA P&B - LP'!$A$1:$F$31,6,0) -> INACTIVO | G2: MERIDA | H2: =VLOOKUP(Tabla3[[#This Row],[NUEVA RUTA]],Tabla1[#All],2,0) -> INACTIVO | I2: =VLOOKUP($A2,Clientes!$A$1:$C$1999,3,0) -> 3J DISTRIBUCION | J2: 61 | K2: =VLOOKUP($J2,'ESTRUCTURA P&B - LP'!$A$1:$F$40,5,0) -> JOSEPH PADILLA 61 | L2: =IFERROR(VLOOKUP($J2,'[2]POTENCIAL X ZONA'!$B$4:$G$21,6,0),0) -> P | M2: =IFERROR(VLOOKUP($A2,'Convenio Clientes'!$D:$F,3,0),"SN CNV") -> 21 | N2: 07 | O2: 15 | P2: INACTIVO | Q2: NO | R2: =VLOOKUP($N2,Tabla2[#All],3,0) -> DISTRIBUIDOR | S2: AV INTERCOMUNAL TURMERO MARACAY CC | T2: BOAVENTURA PB LOC 1 SECTOR ENCRUCIJADA | U2: MERIDA
A3: J317255208 | B3: ADMINISTRADORA SD 1980, C.A | C3: 98 | D3: 98 | E3: =VLOOKUP($D3,'ESTRUCTURA P&B - LP'!$A$1:$F$31,5,0) -> INACTIVO | F3: =VLOOKUP($D3,'ESTRUCTURA P&B - LP'!$A$1:$F$31,6,0) -> INACTIVO | G3: ARAGUA | H3: =VLOOKUP(Tabla3[[#This Row],[NUEVA RUTA]],Tabla1[#All],2,0) -> INACTIVO | I3: =VLOOKUP($A3,Clientes!$A$1:$C$1999,3,0) -> ADMINT SD 1980 | J3: 0 | K3: =VLOOKUP($J3,'ESTRUCTURA P&B - LP'!$A$1:$F$40,5,0) -> INACTIVO | L3: =IFERROR(VLOOKUP($J3,'[2]POTENCIAL X ZONA'!$B$4:$G$21,6,0),0) -> 0 | M3: =IFERROR(VLOOKUP($A3,'Convenio Clientes'!$D:$F,3,0),"SN CNV") -> 01 | N3: 03 | O3: 0 | P3: INACTIVO | Q3: NO | R3: =VLOOKUP($N3,Tabla2[#All],3,0) -> CADENAS - SUPERMERCADOS | S3: CALLE ENTRADA SUR EDIF BONSAI PISO 8 | T3: URB SANTA PAULA CARACAS (EL CAFETAL) | U3: TURMERO
A4: V117414546 | B4: ADRIANA PEREIRO NEGRO | C4: 99 | D4: 99 | E4: =VLOOKUP($D4,'ESTRUCTURA P&B - LP'!$A$1:$F$31,5,0) -> E-COMMERCE | F4: =VLOOKUP($D4,'ESTRUCTURA P&B - LP'!$A$1:$F$31,6,0) -> E-COMMERCE | G4: MIRANDA | H4: =VLOOKUP(Tabla3[[#This Row],[NUEVA RUTA]],Tabla1[#All],2,0) -> E-COMMERCE | I4: =VLOOKUP($A4,Clientes!$A$1:$C$1999,3,0) -> ADRIANA PEREIRO | J4: 99 | K4: =VLOOKUP($J4,'ESTRUCTURA P&B - LP'!$A$1:$F$40,5,0) -> E-COMMERCE | L4: =IFERROR(VLOOKUP($J4,'[2]POTENCIAL X ZONA'!$B$4:$G$21,6,0),0) -> 0 | M4: =IFERROR(VLOOKUP($A4,'Convenio Clientes'!$D:$F,3,0),"SN CNV") -> 50 | N4: 10 | O4: 0 | P4: EVENTUAL | Q4: OFICINA | R4: =VLOOKUP($N4,Tabla2[#All],3,0) -> ATENCION AL CLIENTE | S4: AV UNIVERSIDAD ESQUINA LA PEDRERA A | T4: MARCOS PARRA EDF COLON PISO 04 | U4: CARACAS
A5: J501665958 | B5: AGROMAYOR TOCUYITO, C.A. | C5: 20 | D5: 20 | E5: =VLOOKUP($D5,'ESTRUCTURA P&B - LP'!$A$1:$F$31,5,0) -> JUAN LEÓN 20 | F5: =VLOOKUP($D5,'ESTRUCTURA P&B - LP'!$A$1:$F$31,6,0) -> DUBRASKA PÉREZ | G5: CARABOBO | H5: =VLOOKUP(Tabla3[[#This Row],[NUEVA RUTA]],Tabla1[#All],2,0) -> CENTRO-OCCIDENTE | I5: =VLOOKUP($A5,Clientes!$A$1:$C$1999,3,0) -> AGROM TOCUYITO | J5: 20 | K5: =VLOOKUP($J5,'ESTRUCTURA P&B - LP'!$A$1:$F$40,5,0) -> JUAN LEÓN 20 | L5: =IFERROR(VLOOKUP($J5,'[2]POTENCIAL X ZONA'!$B$4:$G$21,6,0),0) -> P | M5: =IFERROR(VLOOKUP($A5,'Convenio Clientes'!$D:$F,3,0),"SN CNV") -> 21 | N5: 07 | O5: 0 | P5: INACTIVO | Q5: NO | R5: =VLOOKUP($N5,Tabla2[#All],3,0) -> DISTRIBUIDOR | S5: AV. 91 LOCAL NRO 90-250 | T5: BARRIO LIBERTADOR | U5: TOCUYITO
A6: J412594982 | B6: AGROPA, C.A | C6: 99 | D6: 99 | E6: =VLOOKUP($D6,'ESTRUCTURA P&B - LP'!$A$1:$F$31,5,0) -> E-COMMERCE | F6: =VLOOKUP($D6,'ESTRUCTURA P&B - LP'!$A$1:$F$31,6,0) -> E-COMMERCE | G6: PORTUGUESA | H6: =VLOOKUP(Tabla3[[#This Row],[NUEVA RUTA]],Tabla1[#All],2,0) -> E-COMMERCE | I6: =VLOOKUP($A6,Clientes!$A$1:$C$1999,3,0) -> AGROPA, C.A. | J6: 99 | K6: =VLOOKUP($J6,'ESTRUCTURA P&B - LP'!$A$1:$F$40,5,0) -> E-COMMERCE | L6: =IFERROR(VLOOKUP($J6,'[2]POTENCIAL X ZONA'!$B$4:$G$21,6,0),0) -> 0 | M6: =IFERROR(VLOOKUP($A6,'Convenio Clientes'!$D:$F,3,0),"SN CNV") -> 50 | N6: 10 | O6: 0 | P6: EVENTUAL | Q6: OFICINA | R6: =VLOOKUP($N6,Tabla2[#All],3,0) -> ATENCION AL CLIENTE | U6: ARAURE
A7: V096825435 | B7: AIDA CAROLINA MEDINA DIAZ | C7: 98 | D7: 95 | E7: =VLOOKUP($D7,'ESTRUCTURA P&B - LP'!$A$1:$F$31,5,0) -> EVENTUALES | F7: =VLOOKUP($D7,'ESTRUCTURA P&B - LP'!$A$1:$F$31,6,0) -> ROSLI APONTE | G7: DISTRITO CAPITAL | H7: =VLOOKUP(Tabla3[[#This Row],[NUEVA RUTA]],Tabla1[#All],2,0) -> OFICINA | I7: =VLOOKUP($A7,Clientes!$A$1:$C$1999,3,0) -> AIDA C. MEDINA | J7: 95 | K7: =VLOOKUP($J7,'ESTRUCTURA P&B - LP'!$A$1:$F$40,5,0) -> EVENTUALES | L7: =IFERROR(VLOOKUP($J7,'[2]POTENCIAL X ZONA'!$B$4:$G$21,6,0),0) -> 0 | M7: =IFERROR(VLOOKUP($A7,'Convenio Clientes'!$D:$F,3,0),"SN CNV") -> 21 | N7: 09 | O7: 0 | P7: EVENTUAL | Q7: OFICINA | R7: =VLOOKUP($N7,Tabla2[#All],3,0) -> INSTITUCIONAL | S7: CALLE TAMARE ENTRE CABURE Y DABAJURO | T7: LOC-2 SECTOR PUERTA MARAVEN PTA CARDON | U7: CARACAS
A8: J402835604 | B8: ALIADOS COMERCIALES, C.A. | C8: 62 | D8: 21 | E8: =VLOOKUP($D8,'ESTRUCTURA P&B - LP'!$A$1:$F$31,5,0) -> ANDREINA RANGEL 21 | F8: =VLOOKUP($D8,'ESTRUCTURA P&B - LP'!$A$1:$F$31,6,0) -> ANDREINA RANGEL | G8: FALCON | H8: =VLOOKUP(Tabla3[[#This Row],[NUEVA RUTA]],Tabla1[#All],2,0) -> OCCIDENTE | I8: =VLOOKUP($A8,Clientes!$A$1:$C$1999,3,0) -> ALIADOS COMERC | J8: 21 | K8: =VLOOKUP($J8,'ESTRUCTURA P&B - LP'!$A$1:$F$40,5,0) -> ANDREINA RANGEL 21 | L8: =IFERROR(VLOOKUP($J8,'[2]POTENCIAL X ZONA'!$B$4:$G$21,6,0),0) -> S | M8: =IFERROR(VLOOKUP($A8,'Convenio Clientes'!$D:$F,3,0),"SN CNV") -> 20 | N8: 07 | O8: 15 | P8: REGULAR | Q8: SI | R8: =VLOOKUP($N8,Tabla2[#All],3,0) -> DISTRIBUIDOR | S8: AV 91 LOCAL N°80-126 SEC, LA FORTALEZA | T8: BARRIO EL LIBERTADOR | U8: PUNTO FIJO
A9: J402802218 | B9: ALIANZA DISTRIBUIDORA C.A | C9: 98 | D9: 98 | E9: =VLOOKUP($D9,'ESTRUCTURA P&B - LP'!$A$1:$F$31,5,0) -> INACTIVO | F9: =VLOOKUP($D9,'ESTRUCTURA P&B - LP'!$A$1:$F$31,6,0) -> INACTIVO | G9: ZULIA | H9: =VLOOKUP(Tabla3[[#This Row],[NUEVA RUTA]],Tabla1[#All],2,0) -> INACTIVO | I9: =VLOOKUP($A9,Clientes!$A$1:$C$1999,3,0) -> 30 SAN JUAN | J9: 0 | K9: =VLOOKUP($J9,'ESTRUCTURA P&B - LP'!$A$1:$F$40,5,0) -> INACTIVO | L9: =IFERROR(VLOOKUP($J9,'[2]POTENCIAL X ZONA'!$B$4:$G$21,6,0),0) -> 0 | M9: =IFERROR(VLOOKUP($A9,'Convenio Clientes'!$D:$F,3,0),"SN CNV") -> 01 | N9: 07 | O9: 0 | P9: INACTIVO | Q9: NO | R9: =VLOOKUP($N9,Tabla2[#All],3,0) -> DISTRIBUIDOR | S9: CALLE CALLEJON MAÑONGO(176) TERRENO | T9: CIVICO NO.91-A-15 LOCAL 1 NRO.1 | U9: MARACAIBO
A10: J317219686 | B10: ALIMENTOS FM C.A. | C10: 98 | D10: 20 | E10: =VLOOKUP($D10,'ESTRUCTURA P&B - LP'!$A$1:$F$31,5,0) -> JUAN LEÓN 20 | F10: =VLOOKUP($D10,'ESTRUCTURA P&B - LP'!$A$1:$F$31,6,0) -> DUBRASKA PÉREZ | G10: CARABOBO | H10: =VLOOKUP(Tabla3[[#This Row],[NUEVA RUTA]],Tabla1[#All],2,0) -> CENTRO-OCCIDENTE | I10: =VLOOKUP($A10,Clientes!$A$1:$C$1999,3,0) -> ALIMENTOS FM | J10: 20 | K10: =VLOOKUP($J10,'ESTRUCTURA P&B - LP'!$A$1:$F$40,5,0) -> JUAN LEÓN 20 | L10: =IFERROR(VLOOKUP($J10,'[2]POTENCIAL X ZONA'!$B$4:$G$21,6,0),0) -> P | M10: =IFERROR(VLOOKUP($A10,'Convenio Clientes'!$D:$F,3,0),"SN CNV") -> 21 | N10: 03 | O10: 30 | P10: INACTIVO | Q10: NO | R10: =VLOOKUP($N10,Tabla2[#All],3,0) -> CADENAS - SUPERMERCADOS | S10: CALLE PRINCIPAL EL COTIJO DE ORIENTE | T10: EDIF 4 PISO 3 APT 438 CONJUNTO RESIDENCIAL AGUA CLARA | U10: NAGUANAGUA
A11: J500127740 | B11: ALIMENTOS RB 2020, C.A | C11: 20 | D11: 20 | E11: =VLOOKUP($D11,'ESTRUCTURA P&B - LP'!$A$1:$F$31,5,0) -> JUAN LEÓN 20 | F11: =VLOOKUP($D11,'ESTRUCTURA P&B - LP'!$A$1:$F$31,6,0) -> DUBRASKA PÉREZ | G11: CARABOBO | H11: CENTRAL | I11: =VLOOKUP($A11,Clientes!$A$1:$C$1999,3,0) -> ALIMENT RB 2020 | J11: 20 | K11: =VLOOKUP($J11,'ESTRUCTURA P&B - LP'!$A$1:$F$40,5,0) -> JUAN LEÓN 20 | L11: =IFERROR(VLOOKUP($J11,'[2]POTENCIAL X ZONA'!$B$4:$G$21,6,0),0) -> P | M11: =IFERROR(VLOOKUP($A11,'Convenio Clientes'!$D:$F,3,0),"SN CNV") -> 01 | N11: 03 | O11: 0 | P11: INACTIVO | Q11: NO | R11: =VLOOKUP($N11,Tabla2[#All],3,0) -> CADENAS - SUPERMERCADOS | U11: VALENCIA
A12: J406761117 | B12: ALLEVENTS, C.A | C12: 98 | D12: 98 | E12: =VLOOKUP($D12,'ESTRUCTURA P&B - LP'!$A$1:$F$31,5,0) -> INACTIVO | F12: =VLOOKUP($D12,'ESTRUCTURA P&B - LP'!$A$1:$F$31,6,0) -> INACTIVO | G12: ANZOATEGUI | H12: =VLOOKUP(Tabla3[[#This Row],[NUEVA RUTA]],Tabla1[#All],2,0) -> INACTIVO | I12: =VLOOKUP($A12,Clientes!$A$1:$C$1999,3,0) -> ALLEVENTS, C.A | J12: 51 | K12: =VLOOKUP($J12,'ESTRUCTURA P&B - LP'!$A$1:$F$40,5,0) -> DIANA DELGADO 51 | L12: =IFERROR(VLOOKUP($J12,'[2]POTENCIAL X ZONA'!$B$4:$G$21,6,0),0) -> P | M12: =IFERROR(VLOOKUP($A12,'Convenio Clientes'!$D:$F,3,0),"SN CNV") -> 20 | N12: 07 | O12: 0 | P12: INACTIVO | Q12: NO | R12: =VLOOKUP($N12,Tabla2[#All],3,0) -> DISTRIBUIDOR | S12: CALLE NIVEL 1 CASA | T12: PARCELA NRO 9-10 ZONA INDUSTRIAL | U12: BARCELONA
A13: J500014325 | B13: ALMACENADORA MILROSS, C.A. | C13: 98 | D13: 98 | E13: =VLOOKUP($D13,'ESTRUCTURA P&B - LP'!$A$1:$F$31,5,0) -> INACTIVO | F13: =VLOOKUP($D13,'ESTRUCTURA P&B - LP'!$A$1:$F$31,6,0) -> INACTIVO | G13: DISTRITO CAPITAL | H13: =VLOOKUP(Tabla3[[#This Row],[NUEVA RUTA]],Tabla1[#All],2,0) -> INACTIVO | I13: =VLOOKUP($A13,Clientes!$A$1:$C$1999,3,0) -> ALMAC MILROSS | J13: 0 | K13: =VLOOKUP($J13,'ESTRUCTURA P&B - LP'!$A$1:$F$40,5,0) -> INACTIVO | L13: =IFERROR(VLOOKUP($J13,'[2]POTENCIAL X ZONA'!$B$4:$G$21,6,0),0) -> 0 | M13: =IFERROR(VLOOKUP($A13,'Convenio Clientes'!$D:$F,3,0),"SN CNV") -> 21 | N13: 07 | O13: 0 | P13: INACTIVO | Q13: NO | R13: =VLOOKUP($N13,Tabla2[#All],3,0) -> DISTRIBUIDOR | S13: AV RIO CAURA CON AV RIO PARAGUA | T13: CC CONCRESA NIVEL 2 LOCAL 111 | U13: CARACAS
A14: J312054280 | B14: AMBIENTADORES ALNI DE VENEZUELA,AMBIVEN,C.A. | C14: 98 | D14: 98 | E14: =VLOOKUP($D14,'ESTRUCTURA P&B - LP'!$A$1:$F$31,5,0) -> INACTIVO | F14: =VLOOKUP($D14,'ESTRUCTURA P&B - LP'!$A$1:$F$31,6,0) -> INACTIVO | G14: MIRANDA | H14: =VLOOKUP(Tabla3[[#This Row],[NUEVA RUTA]],Tabla1[#All],2,0) -> INACTIVO | I14: =VLOOKUP($A14,Clientes!$A$1:$C$1999,3,0) -> AMBIVEN | J14: 95 | K14: =VLOOKUP($J14,'ESTRUCTURA P&B - LP'!$A$1:$F$40,5,0) -> EVENTUALES | L14: =IFERROR(VLOOKUP($J14,'[2]POTENCIAL X ZONA'!$B$4:$G$21,6,0),0) -> 0 | M14: =IFERROR(VLOOKUP($A14,'Convenio Clientes'!$D:$F,3,0),"SN CNV") -> 01 | N14: 07 | O14: 0 | P14: INACTIVO | Q14: NO | R14: =VLOOKUP($N14,Tabla2[#All],3,0) -> DISTRIBUIDOR | S14: URB GUACARA LOS GUAYOS 1ERA ETAPA DE | T14: CIUDAD ALIANZA C.C. ALIANZA MALL PB | U14: CARACAS
A15: J503504641 | B15: AMI DISTRIBUIDORA Y COMERCIALIZADORA , C.A | C15: 23 | D15: 23 | E15: =VLOOKUP($D15,'ESTRUCTURA P&B - LP'!$A$1:$F$31,5,0) -> MARTHA VILORIA | F15: =VLOOKUP($D15,'ESTRUCTURA P&B - LP'!$A$1:$F$31,6,0) -> DUBRASKA PÉREZ | G15: LARA | H15: =VLOOKUP(Tabla3[[#This Row],[NUEVA RUTA]],Tabla1[#All],2,0) -> CENTRO-OCCIDENTE | I15: =VLOOKUP($A15,Clientes!$A$1:$C$1999,3,0) -> AMI DISTRIB | J15: 23 | K15: =VLOOKUP($J15,'ESTRUCTURA P&B - LP'!$A$1:$F$40,5,0) -> MARTHA VILORIA | L15: =IFERROR(VLOOKUP($J15,'[2]POTENCIAL X ZONA'!$B$4:$G$21,6,0),0) -> S | M15: =IFERROR(VLOOKUP($A15,'Convenio Clientes'!$D:$F,3,0),"SN CNV") -> 26 | N15: 07 | O15: 15 | P15: REGULAR | Q15: SI | R15: =VLOOKUP($N15,Tabla2[#All],3,0) -> DISTRIBUIDOR | U15: BARQUISIMETO
A16: J312492031 | B16: AMIFARMACIA, C.A. | C16: 98 | D16: 98 | E16: =VLOOKUP($D16,'ESTRUCTURA P&B - LP'!$A$1:$F$31,5,0) -> INACTIVO | F16: =VLOOKUP($D16,'ESTRUCTURA P&B - LP'!$A$1:$F$31,6,0) -> INACTIVO | G16: CARABOBO | H16: =VLOOKUP(Tabla3[[#This Row],[NUEVA RUTA]],Tabla1[#All],2,0) -> INACTIVO | I16: =VLOOKUP($A16,Clientes!$A$1:$C$1999,3,0) -> 65 LOCATEL | J16: 20 | K16: =VLOOKUP($J16,'ESTRUCTURA P&B - LP'!$A$1:$F$40,5,0) -> JUAN LEÓN 20 | L16: =IFERROR(VLOOKUP($J16,'[2]POTENCIAL X ZONA'!$B$4:$G$21,6,0),0) -> P | M16: =IFERROR(VLOOKUP($A16,'Convenio Clientes'!$D:$F,3,0),"SN CNV") -> 01 | N16: 01 | O16: 15 | P16: INACTIVO | Q16: NO | R16: =VLOOKUP($N16,Tabla2[#All],3,0) -> CADENAS - FARMACIAS | S16: AV 1ERA CON 10MA | T16: EDIF RES DORAMIL PISO PB APT 2 | U16: LOS GUAYOS
A17: V068206150 | B17: ANA MARIA PONCE SARDI | C17: 95 | D17: 90 | E17: =VLOOKUP($D17,'ESTRUCTURA P&B - LP'!$A$1:$F$31,5,0) -> INTER-COMPAÑÍA | F17: =VLOOKUP($D17,'ESTRUCTURA P&B - LP'!$A$1:$F$31,6,0) -> ROSLI APONTE | G17: MIRANDA | H17: =VLOOKUP(Tabla3[[#This Row],[NUEVA RUTA]],Tabla1[#All],2,0) -> OFICINA | I17: =VLOOKUP($A17,Clientes!$A$1:$C$1999,3,0) -> ANA MARIA PONCE | J17: 90 | K17: =VLOOKUP($J17,'ESTRUCTURA P&B - LP'!$A$1:$F$40,5,0) -> INTER-COMPAÑÍA | L17: =IFERROR(VLOOKUP($J17,'[2]POTENCIAL X ZONA'!$B$4:$G$21,6,0),0) -> 0 | M17: =IFERROR(VLOOKUP($A17,'Convenio Clientes'!$D:$F,3,0),"SN CNV") -> 21 | N17: 11 | O17: 0 | P17: EVENTUAL | Q17: OFICINA | R17: =VLOOKUP($N17,Tabla2[#All],3,0) -> EMPLEADOS | S17: AV. TEHERAN EDIF JUAN VIVES SURIA PISO 6 APTO 1A06A | T17: MONTALBAN III | U17: CARACAS
A18: V225666314 | B18: ANAROSBER PAREJO REYES | C18: 99 | D18: 99 | E18: =VLOOKUP($D18,'ESTRUCTURA P&B - LP'!$A$1:$F$31,5,0) -> E-COMMERCE | F18: =VLOOKUP($D18,'ESTRUCTURA P&B - LP'!$A$1:$F$31,6,0) -> E-COMMERCE | G18: MIRANDA | H18: =VLOOKUP(Tabla3[[#This Row],[NUEVA RUTA]],Tabla1[#All],2,0) -> E-COMMERCE | I18: =VLOOKUP($A18,Clientes!$A$1:$C$1999,3,0) -> ANAROSBER PAREJ | J18: 99 | K18: =VLOOKUP($J18,'ESTRUCTURA P&B - LP'!$A$1:$F$40,5,0) -> E-COMMERCE | L18: =IFERROR(VLOOKUP($J18,'[2]POTENCIAL X ZONA'!$B$4:$G$21,6,0),0) -> 0 | M18: =IFERROR(VLOOKUP($A18,'Convenio Clientes'!$D:$F,3,0),"SN CNV") -> 50 | N18: 10 | O18: 0 | P18: EVENTUAL | Q18: OFICINA | R18: =VLOOKUP($N18,Tabla2[#All],3,0) -> ATENCION AL CLIENTE | U18: CHARALLAVE
A19: V141955400 | B19: ANGEL ALEXIS SAYAGO | C19: 98 | D19: 98 | E19: =VLOOKUP($D19,'ESTRUCTURA P&B - LP'!$A$1:$F$31,5,0) -> INACTIVO | F19: =VLOOKUP($D19,'ESTRUCTURA P&B - LP'!$A$1:$F$31,6,0) -> INACTIVO | G19: DISTRITO CAPITAL | H19: =VLOOKUP(Tabla3[[#This Row],[NUEVA RUTA]],Tabla1[#All],2,0) -> INACTIVO | I19: =VLOOKUP($A19,Clientes!$A$1:$C$1999,3,0) -> ANGEL A SAYAGO | J19: 90 | K19: =VLOOKUP($J19,'ESTRUCTURA P&B - LP'!$A$1:$F$40,5,0) -> INTER-COMPAÑÍA | L19: =IFERROR(VLOOKUP($J19,'[2]POTENCIAL X ZONA'!$B$4:$G$21,6,0),0) -> 0 | M19: =IFERROR(VLOOKUP($A19,'Convenio Clientes'!$D:$F,3,0),"SN CNV") -> 21 | N19: 09 | O19: 0 | P19: INACTIVO | Q19: NO | R19: =VLOOKUP($N19,Tabla2[#All],3,0) -> INSTITUCIONAL | S19: AV BERMUDEZ CON LA AVENIDA MIRANDA | T19: LOCAL DIAGONAL A LA PLAZA BOLIVAR | U19: CARACAS
A20: J412891260 | B20: ARABITO MARKET, C.A. | C20: 98 | D20: 12 | E20: =VLOOKUP($D20,'ESTRUCTURA P&B - LP'!$A$1:$F$31,5,0) -> JUAN LEÓN 12 | F20: =VLOOKUP($D20,'ESTRUCTURA P&B - LP'!$A$1:$F$31,6,0) -> DUBRASKA PÉREZ | G20: ARAGUA | H20: =VLOOKUP(Tabla3[[#This Row],[NUEVA RUTA]],Tabla1[#All],2,0) -> CENTRO-OCCIDENTE | I20: =VLOOKUP($A20,Clientes!$A$1:$C$1999,3,0) -> ARABITO MARKET | J20: 12 | K20: =VLOOKUP($J20,'ESTRUCTURA P&B - LP'!$A$1:$F$40,5,0) -> JUAN LEÓN 12 | L20: =IFERROR(VLOOKUP($J20,'[2]POTENCIAL X ZONA'!$B$4:$G$21,6,0),0) -> P | M20: =IFERROR(VLOOKUP($A20,'Convenio Clientes'!$D:$F,3,0),"SN CNV") -> 21 | N20: 03 | O20: 45 | P20: EVENTUAL | Q20: SI | R20: =VLOOKUP($N20,Tabla2[#All],3,0) -> CADENAS - SUPERMERCADOS | S20: AV BOLIVAR CASA NRO 6 -12 SECTOR LA | U20: MARACAY
A21: J298008040 | B21: ARCO SUMINISTROS, C.A. | C21: 98 | D21: 98 | E21: =VLOOKUP($D21,'ESTRUCTURA P&B - LP'!$A$1:$F$31,5,0) -> INACTIVO | F21: =VLOOKUP($D21,'ESTRUCTURA P&B - LP'!$A$1:$F$31,6,0) -> INACTIVO | G21: MERIDA | H21: =VLOOKUP(Tabla3[[#This Row],[NUEVA RUTA]],Tabla1[#All],2,0) -> INACTIVO | I21: =VLOOKUP($A21,Clientes!$A$1:$C$1999,3,0) -> ARCO SUMINISTRO | J21: 0 | K21: =VLOOKUP($J21,'ESTRUCTURA P&B - LP'!$A$1:$F$40,5,0) -> INACTIVO | L21: =IFERROR(VLOOKUP($J21,'[2]POTENCIAL X ZONA'!$B$4:$G$21,6,0),0) -> 0 | M21: =IFERROR(VLOOKUP($A21,'Convenio Clientes'!$D:$F,3,0),"SN CNV") -> 01 | N21: 07 | O21: 0 | P21: INACTIVO | Q21: NO | R21: =VLOOKUP($N21,Tabla2[#All],3,0) -> DISTRIBUIDOR | S21: AV LAS ESCUELAS EDIF CAJA DE AHORRO | T21: DEL EJERCITO BOLIVARIANO PISO PB | U21: MERIDA
A22: J294462847 | B22: ASOC CIVIL CAJA DE AHORRO DEL EJERC BOLIVARIANO | C22: 98 | D22: 98 | E22: =VLOOKUP($D22,'ESTRUCTURA P&B - LP'!$A$1:$F$31,5,0) -> INACTIVO | F22: =VLOOKUP($D22,'ESTRUCTURA P&B - LP'!$A$1:$F$31,6,0) -> INACTIVO | G22: DISTRITO CAPITAL | H22: =VLOOKUP(Tabla3[[#This Row],[NUEVA RUTA]],Tabla1[#All],2,0) -> INACTIVO | I22: =VLOOKUP($A22,Clientes!$A$1:$C$1999,3,0) -> EJERC BOLIVARIA | J22: 0 | K22: =VLOOKUP($J22,'ESTRUCTURA P&B - LP'!$A$1:$F$40,5,0) -> INACTIVO | L22: =IFERROR(VLOOKUP($J22,'[2]POTENCIAL X ZONA'!$B$4:$G$21,6,0),0) -> 0 | M22: =IFERROR(VLOOKUP($A22,'Convenio Clientes'!$D:$F,3,0),"SN CNV") -> 01 | N22: 09 | O22: 0 | P22: INACTIVO | Q22: NO | R22: =VLOOKUP($N22,Tabla2[#All],3,0) -> INSTITUCIONAL | S22: AV 3RA CON 6TA TRANSV EDIF INTER | T22: PISO 3 OF ALTAMIRA URB ALTAMIRA | U22: CARACAS
A23: J308487406 | B23: ASOC CIVIL INSTITUTO DE TEOLOGIA PARA RELIGIOSOS | C23: 95 | D23: 95 | E23: =VLOOKUP($D23,'ESTRUCTURA P&B - LP'!$A$1:$F$31,5,0) -> EVENTUALES | F23: =VLOOKUP($D23,'ESTRUCTURA P&B - LP'!$A$1:$F$31,6,0) -> ROSLI APONTE | G23: MIRANDA | H23: =VLOOKUP(Tabla3[[#This Row],[NUEVA RUTA]],Tabla1[#All],2,0) -> OFICINA | I23: =VLOOKUP($A23,Clientes!$A$1:$C$1999,3,0) -> ASOC C TEOLOGIA | J23: 95 | K23: =VLOOKUP($J23,'ESTRUCTURA P&B - LP'!$A$1:$F$40,5,0) -> EVENTUALES | L23: =IFERROR(VLOOKUP($J23,'[2]POTENCIAL X ZONA'!$B$4:$G$21,6,0),0) -> 0 | M23: =IFERROR(VLOOKUP($A23,'Convenio Clientes'!$D:$F,3,0),"SN CNV") -> 21 | N23: 09 | O23: 0 | P23: EVENTUAL | Q23: OFICINA | R23: =VLOOKUP($N23,Tabla2[#All],3,0) -> INSTITUCIONAL | S23: AV. SAN FELIPE | T23: EDIFICIO DON BOSCO 88 PISO 1 | U23: CARACAS
A24: J001222642 | B24: ASOCIACION DAMAS SALESIANAS | C24: 98 | D24: 95 | E24: =VLOOKUP($D24,'ESTRUCTURA P&B - LP'!$A$1:$F$31,5,0) -> EVENTUALES | F24: =VLOOKUP($D24,'ESTRUCTURA P&B - LP'!$A$1:$F$31,6,0) -> ROSLI APONTE | G24: MIRANDA | H24: =VLOOKUP(Tabla3[[#This Row],[NUEVA RUTA]],Tabla1[#All],2,0) -> OFICINA | I24: =VLOOKUP($A24,Clientes!$A$1:$C$1999,3,0) -> ASOC DAMAS SALE | J24: 90 | K24: =VLOOKUP($J24,'ESTRUCTURA P&B - LP'!$A$1:$F$40,5,0) -> INTER-COMPAÑÍA | L24: =IFERROR(VLOOKUP($J24,'[2]POTENCIAL X ZONA'!$B$4:$G$21,6,0),0) -> 0 | M24: =IFERROR(VLOOKUP($A24,'Convenio Clientes'!$D:$F,3,0),"SN CNV") -> 21 | N24: 17 | O24: 0 | P24: EVENTUAL | Q24: OFICINA | R24: =VLOOKUP($N24,Tabla2[#All],3,0) -> OTROS | S24: AV. LA ESTANCIA CC C.C.C.TAMANACO, | T24: TORRE C NIVEL 13 OFICINA 1304 | U24: CARACAS
A25: J404498923 | B25: ASOCOMPRA ASOCIACIÓN DE COMPRADORES, A.C. | C25: 98 | D25: 98 | E25: =VLOOKUP($D25,'ESTRUCTURA P&B - LP'!$A$1:$F$31,5,0) -> INACTIVO | F25: =VLOOKUP($D25,'ESTRUCTURA P&B - LP'!$A$1:$F$31,6,0) -> INACTIVO | G25: MIRANDA | H25: =VLOOKUP(Tabla3[[#This Row],[NUEVA RUTA]],Tabla1[#All],2,0) -> INACTIVO | I25: =VLOOKUP($A25,Clientes!$A$1:$C$1999,3,0) -> ASOCOMPRA | J25: 10 | K25: =VLOOKUP($J25,'ESTRUCTURA P&B - LP'!$A$1:$F$40,5,0) -> MILAGROS FERNANDEZ 10 | L25: =IFERROR(VLOOKUP($J25,'[2]POTENCIAL X ZONA'!$B$4:$G$21,6,0),0) -> B | M25: =IFERROR(VLOOKUP($A25,'Convenio Clientes'!$D:$F,3,0),"SN CNV") -> 20 | N25: 09 | O25: 7 | P25: INACTIVO | Q25: NO | R25: =VLOOKUP($N25,Tabla2[#All],3,0) -> INSTITUCIONAL | S25: ZONA IND. LAS VEGAS 1RA TRANSVERSAL | T25: PARCELA 18 | U25: CARACAS
A26: J504755699 | B26: ATLANTICO CENTER PZO, C.A | C26: 52 | D26: 52 | E26: =VLOOKUP($D26,'ESTRUCTURA P&B - LP'!$A$1:$F$31,5,0) -> DIANA DELGADO 52 | F26: =VLOOKUP($D26,'ESTRUCTURA P&B - LP'!$A$1:$F$31,6,0) -> DIANA DELGADO | G26: BOLIVAR | H26: ORIENTE SUR | I26: =VLOOKUP($A26,Clientes!$A$1:$C$1999,3,0) -> ATLANTIC CENTER | J26: 52 | K26: =VLOOKUP($J26,'ESTRUCTURA P&B - LP'!$A$1:$F$40,5,0) -> DIANA DELGADO 52 | L26: =IFERROR(VLOOKUP($J26,'[2]POTENCIAL X ZONA'!$B$4:$G$21,6,0),0) -> S | M26: =IFERROR(VLOOKUP($A26,'Convenio Clientes'!$D:$F,3,0),"SN CNV") -> 20 | N26: 07 | O26: 0 | P26: EVENTUAL | Q26: SI | R26: =VLOOKUP($N26,Tabla2[#All],3,0) -> DISTRIBUIDOR | U26: CIUDAD GUAYANA
A27: J504648450 | B27: AURA STUDIO 2022, CA | C27: 99 | D27: 99 | E27: =VLOOKUP($D27,'ESTRUCTURA P&B - LP'!$A$1:$F$31,5,0) -> E-COMMERCE | F27: =VLOOKUP($D27,'ESTRUCTURA P&B - LP'!$A$1:$F$31,6,0) -> E-COMMERCE | G27: MIRANDA | H27: =VLOOKUP(Tabla3[[#This Row],[NUEVA RUTA]],Tabla1[#All],2,0) -> E-COMMERCE | I27: =VLOOKUP($A27,Clientes!$A$1:$C$1999,3,0) -> AURA STUDIO2022 | J27: 99 | K27: =VLOOKUP($J27,'ESTRUCTURA P&B - LP'!$A$1:$F$40,5,0) -> E-COMMERCE | L27: =IFERROR(VLOOKUP($J27,'[2]POTENCIAL X ZONA'!$B$4:$G$21,6,0),0) -> 0 | M27: =IFERROR(VLOOKUP($A27,'Convenio Clientes'!$D:$F,3,0),"SN CNV") -> 50 | N27: 10 | O27: 0 | P27: EVENTUAL | Q27: OFICINA | R27: =VLOOKUP($N27,Tabla2[#All],3,0) -> ATENCION AL CLIENTE | S27: 0 | T27: 0 | U27: CARACAS
A28: J075245113 | B28: AUTO MERCADO SAN DIEGO, C.A. | C28: 98 | D28: 12 | E28: =VLOOKUP($D28,'ESTRUCTURA P&B - LP'!$A$1:$F$31,5,0) -> JUAN LEÓN 12 | F28: =VLOOKUP($D28,'ESTRUCTURA P&B - LP'!$A$1:$F$31,6,0) -> DUBRASKA PÉREZ | G28: ARAGUA | H28: =VLOOKUP(Tabla3[[#This Row],[NUEVA RUTA]],Tabla1[#All],2,0) -> CENTRO-OCCIDENTE | I28: =VLOOKUP($A28,Clientes!$A$1:$C$1999,3,0) -> 37 SAN DIEGO | J28: 12 | K28: =VLOOKUP($J28,'ESTRUCTURA P&B - LP'!$A$1:$F$40,5,0) -> JUAN LEÓN 12 | L28: =IFERROR(VLOOKUP($J28,'[2]POTENCIAL X ZONA'!$B$4:$G$21,6,0),0) -> P | M28: =IFERROR(VLOOKUP($A28,'Convenio Clientes'!$D:$F,3,0),"SN CNV") -> 21 | N28: 03 | O28: 0 | P28: EVENTUAL | Q28: SI | R28: =VLOOKUP($N28,Tabla2[#All],3,0) -> CADENAS - SUPERMERCADOS | S28: AV OESTE 16 ESQUINA COCHERA | T28: LOCAL PLANTA BAJA NRO 38 | U28: CAGUA
A29: J413118440 | B29: AUTOMERCADO CHINATOWN SAN JUAN 2020, C.A | C29: 98 | D29: 98 | E29: =VLOOKUP($D29,'ESTRUCTURA P&B - LP'!$A$1:$F$31,5,0) -> INACTIVO | F29: =VLOOKUP($D29,'ESTRUCTURA P&B - LP'!$A$1:$F$31,6,0) -> INACTIVO | G29: DISTRITO CAPITAL | H29: =VLOOKUP(Tabla3[[#This Row],[NUEVA RUTA]],Tabla1[#All],2,0) -> INACTIVO | I29: =VLOOKUP($A29,Clientes!$A$1:$C$1999,3,0) -> CHINAT SAN JUAN | J29: 57 | K29: =VLOOKUP($J29,'ESTRUCTURA P&B - LP'!$A$1:$F$40,5,0) -> CARLOS ZURITA | L29: =IFERROR(VLOOKUP($J29,'[2]POTENCIAL X ZONA'!$B$4:$G$21,6,0),0) -> 0 | M29: =IFERROR(VLOOKUP($A29,'Convenio Clientes'!$D:$F,3,0),"SN CNV") -> 21 | N29: 15 | O29: 7 | P29: INACTIVO | Q29: NO | R29: =VLOOKUP($N29,Tabla2[#All],3,0) -> MAYORISTAS | S29: CTRA NACIONAL SAN CRISOBAL-CAPACHO | T29: L GALPON SEC ZORCA PROVIDENCIA | U29: CARACAS
A30: J304983905 | B30: AUTOMERCADO COSMO FRONTERA, C.A | C30: 98 | D30: 98 | E30: =VLOOKUP($D30,'ESTRUCTURA P&B - LP'!$A$1:$F$31,5,0) -> INACTIVO | F30: =VLOOKUP($D30,'ESTRUCTURA P&B - LP'!$A$1:$F$31,6,0) -> INACTIVO | G30: TACHIRA | H30: =VLOOKUP(Tabla3[[#This Row],[NUEVA RUTA]],Tabla1[#All],2,0) -> INACTIVO | I30: =VLOOKUP($A30,Clientes!$A$1:$C$1999,3,0) -> AUT COSMO FRONT | J30: 0 | K30: =VLOOKUP($J30,'ESTRUCTURA P&B - LP'!$A$1:$F$40,5,0) -> INACTIVO | L30: =IFERROR(VLOOKUP($J30,'[2]POTENCIAL X ZONA'!$B$4:$G$21,6,0),0) -> 0 | M30: =IFERROR(VLOOKUP($A30,'Convenio Clientes'!$D:$F,3,0),"SN CNV") -> 01 | N30: 06 | O30: 0 | P30: INACTIVO | Q30: NO | R30: =VLOOKUP($N30,Tabla2[#All],3,0) -> SUPERMERCADOS INDEPENDIENTES | S30: 3rA CON 5tA TRANSV.LOS PALOS GDES.URB. | T30: LOS PALOS GRANDES C.C.EL PATIO LC 7-8 | U30: SAN CRISTOBAL
A31: J000859400 | B31: AUTOMERCADO EL PATIO LOS PALOS GRANDES, C.A. | C31: 98 | D31: 98 | E31: =VLOOKUP($D31,'ESTRUCTURA P&B - LP'!$A$1:$F$31,5,0) -> INACTIVO | F31: =VLOOKUP($D31,'ESTRUCTURA P&B - LP'!$A$1:$F$31,6,0) -> INACTIVO | G31: MIRANDA | H31: =VLOOKUP(Tabla3[[#This Row],[NUEVA RUTA]],Tabla1[#All],2,0) -> INACTIVO | I31: =VLOOKUP($A31,Clientes!$A$1:$C$1999,3,0) -> 70 EL PATIO | J31: 0 | K31: =VLOOKUP($J31,'ESTRUCTURA P&B - LP'!$A$1:$F$40,5,0) -> INACTIVO | L31: =IFERROR(VLOOKUP($J31,'[2]POTENCIAL X ZONA'!$B$4:$G$21,6,0),0) -> 0 | M31: =IFERROR(VLOOKUP($A31,'Convenio Clientes'!$D:$F,3,0),"SN CNV") -> 01 | N31: 03 | O31: 0 | P31: INACTIVO | Q31: NO | R31: =VLOOKUP($N31,Tabla2[#All],3,0) -> CADENAS - SUPERMERCADOS | S31: AV LA TRINIDAD EL HATILLO CON CALLE EL MURO | T31: EDIF NRO 1PISO PB LOCAL LA MURALLA URB EL HATILLO | U31: CARACAS
A32: J500412940 | B32: AUTOMERCADO LA MURALLA 1061 C.A | C32: 57 | D32: 10 | E32: =VLOOKUP($D32,'ESTRUCTURA P&B - LP'!$A$1:$F$31,5,0) -> MILAGROS FERNANDEZ 10 | F32: =VLOOKUP($D32,'ESTRUCTURA P&B - LP'!$A$1:$F$31,6,0) -> MILAGROS FERNANDEZ | G32: MIRANDA | H32: =VLOOKUP(Tabla3[[#This Row],[NUEVA RUTA]],Tabla1[#All],2,0) -> CAPITAL | I32: =VLOOKUP($A32,Clientes!$A$1:$C$1999,3,0) -> AUT LA MURALLA | J32: 10 | K32: =VLOOKUP($J32,'ESTRUCTURA P&B - LP'!$A$1:$F$40,5,0) -> MILAGROS FERNANDEZ 10 | L32: =IFERROR(VLOOKUP($J32,'[2]POTENCIAL X ZONA'!$B$4:$G$21,6,0),0) -> B | M32: =IFERROR(VLOOKUP($A32,'Convenio Clientes'!$D:$F,3,0),"SN CNV") -> 22 | N32: 06 | O32: 30 | P32: REGULAR | Q32: SI | R32: =VLOOKUP($N32,Tabla2[#All],3,0) -> SUPERMERCADOS INDEPENDIENTES | U32: CARACAS
A33: J003720224 | B33: AUTOMERCADO LA MURALLA C.A. | C33: 57 | D33: 10 | E33: =VLOOKUP($D33,'ESTRUCTURA P&B - LP'!$A$1:$F$31,5,0) -> MILAGROS FERNANDEZ 10 | F33: =VLOOKUP($D33,'ESTRUCTURA P&B - LP'!$A$1:$F$31,6,0) -> MILAGROS FERNANDEZ | G33: MIRANDA | H33: =VLOOKUP(Tabla3[[#This Row],[NUEVA RUTA]],Tabla1[#All],2,0) -> CAPITAL | I33: =VLOOKUP($A33,Clientes!$A$1:$C$1999,3,0) -> AUT LA MURALLA | J33: 10 | K33: =VLOOKUP($J33,'ESTRUCTURA P&B - LP'!$A$1:$F$40,5,0) -> MILAGROS FERNANDEZ 10 | L33: =IFERROR(VLOOKUP($J33,'[2]POTENCIAL X ZONA'!$B$4:$G$21,6,0),0) -> B | M33: =IFERROR(VLOOKUP($A33,'Convenio Clientes'!$D:$F,3,0),"SN CNV") -> 22 | N33: 06 | O33: 30 | P33: REGULAR | Q33: SI | R33: =VLOOKUP($N33,Tabla2[#All],3,0) -> SUPERMERCADOS INDEPENDIENTES | S33: AV FRANCISCO DE MIRANDA CON SAN IGNACIO DE LOYOLA | T33: EDIF VALMY PISO 2 OF 22 | U33: CARACAS
A34: J000811601 | B34: AUTOMERCADO LUZ C.A. | C34: 98 | D34: 98 | E34: =VLOOKUP($D34,'ESTRUCTURA P&B - LP'!$A$1:$F$31,5,0) -> INACTIVO | F34: =VLOOKUP($D34,'ESTRUCTURA P&B - LP'!$A$1:$F$31,6,0) -> INACTIVO | G34: MIRANDA | H34: =VLOOKUP(Tabla3[[#This Row],[NUEVA RUTA]],Tabla1[#All],2,0) -> INACTIVO | I34: =VLOOKUP($A34,Clientes!$A$1:$C$1999,3,0) -> AUTOMERCADO LUZ | J34: 95 | K34: =VLOOKUP($J34,'ESTRUCTURA P&B - LP'!$A$1:$F$40,5,0) -> EVENTUALES | L34: =IFERROR(VLOOKUP($J34,'[2]POTENCIAL X ZONA'!$B$4:$G$21,6,0),0) -> 0 | M34: =IFERROR(VLOOKUP($A34,'Convenio Clientes'!$D:$F,3,0),"SN CNV") -> 21 | N34: 03 | O34: 45 | P34: INACTIVO | Q34: NO | R34: =VLOOKUP($N34,Tabla2[#All],3,0) -> CADENAS - SUPERMERCADOS | S34: 6TA. TRANSV. ENTRE ALTAMIRA Y LOS | T34: PALOS GRANDES, ALTAMIRA QUINTA AKOBA | U34: CARACAS
A35: J000537585 | B35: AUTOMERCADO SAN LORENZO C.A. | C35: 98 | D35: 98 | E35: =VLOOKUP($D35,'ESTRUCTURA P&B - LP'!$A$1:$F$31,5,0) -> INACTIVO | F35: =VLOOKUP($D35,'ESTRUCTURA P&B - LP'!$A$1:$F$31,6,0) -> INACTIVO | G35: MIRANDA | H35: =VLOOKUP(Tabla3[[#This Row],[NUEVA RUTA]],Tabla1[#All],2,0) -> INACTIVO | I35: =VLOOKUP($A35,Clientes!$A$1:$C$1999,3,0) -> AUT SAN LORENZO | J35: 57 | K35: =VLOOKUP($J35,'ESTRUCTURA P&B - LP'!$A$1:$F$40,5,0) -> CARLOS ZURITA | L35: =IFERROR(VLOOKUP($J35,'[2]POTENCIAL X ZONA'!$B$4:$G$21,6,0),0) -> 0 | M35: =IFERROR(VLOOKUP($A35,'Convenio Clientes'!$D:$F,3,0),"SN CNV") -> 01 | N35: 06 | O35: 7 | P35: INACTIVO | Q35: NO | R35: =VLOOKUP($N35,Tabla2[#All],3,0) -> SUPERMERCADOS INDEPENDIENTES | S35: CALLE A C/ CALLE C EDIF LAS ROSAS PISO | T35: PB LOCAL 1-6 URB SANTA ROSA DE LIMA | U35: CARACAS
A36: J002099712 | B36: AUTOMERCADO SANTA ROSA DE LIMA C.A | C36: 98 | D36: 98 | E36: =VLOOKUP($D36,'ESTRUCTURA P&B - LP'!$A$1:$F$31,5,0) -> INACTIVO | F36: =VLOOKUP($D36,'ESTRUCTURA P&B - LP'!$A$1:$F$31,6,0) -> INACTIVO | G36: MIRANDA | H36: =VLOOKUP(Tabla3[[#This Row],[NUEVA RUTA]],Tabla1[#All],2,0) -> INACTIVO | I36: =VLOOKUP($A36,Clientes!$A$1:$C$1999,3,0) -> STA ROSA LIMA | J36: 57 | K36: =VLOOKUP($J36,'ESTRUCTURA P&B - LP'!$A$1:$F$40,5,0) -> CARLOS ZURITA | L36: =IFERROR(VLOOKUP($J36,'[2]POTENCIAL X ZONA'!$B$4:$G$21,6,0),0) -> 0 | M36: =IFERROR(VLOOKUP($A36,'Convenio Clientes'!$D:$F,3,0),"SN CNV") -> 01 | N36: 06 | O36: 7 | P36: INACTIVO | Q36: NO | R36: =VLOOKUP($N36,Tabla2[#All],3,0) -> SUPERMERCADOS INDEPENDIENTES | S36: CTRA PANAMERICANA KM 20, CALLE LOS PINOS | T36: LOCAL NRO N° 1 y 2 SECTOR CORRALITO | U36: CARACAS
A37: J298782366 | B37: AUTOMERCADOS FRESCO MARKET AFN C.A. | C37: 50 | D37: 10 | E37: =VLOOKUP($D37,'ESTRUCTURA P&B - LP'!$A$1:$F$31,5,0) -> MILAGROS FERNANDEZ 10 | F37: =VLOOKUP($D37,'ESTRUCTURA P&B - LP'!$A$1:$F$31,6,0) -> MILAGROS FERNANDEZ | G37: MIRANDA | H37: =VLOOKUP(Tabla3[[#This Row],[NUEVA RUTA]],Tabla1[#All],2,0) -> CAPITAL | I37: =VLOOKUP($A37,Clientes!$A$1:$C$1999,3,0) -> 66 FRESC.MARKET | J37: 10 | K37: =VLOOKUP($J37,'ESTRUCTURA P&B - LP'!$A$1:$F$40,5,0) -> MILAGROS FERNANDEZ 10 | L37: =IFERROR(VLOOKUP($J37,'[2]POTENCIAL X ZONA'!$B$4:$G$21,6,0),0) -> B | M37: =IFERROR(VLOOKUP($A37,'Convenio Clientes'!$D:$F,3,0),"SN CNV") -> 22 | N37: 06 | O37: 30 | P37: REGULAR | Q37: SI | R37: =VLOOKUP($N37,Tabla2[#All],3,0) -> SUPERMERCADOS INDEPENDIENTES | S37: CALLE SOJO CON CALLE CARABOBO | T37: QTA. IBAIONDO NRO N/A | U37: CARRIZAL
A38: J305113530 | B38: AUTOMERCADOS KLASSE, C.A. | C38: 98 | D38: 98 | E38: =VLOOKUP($D38,'ESTRUCTURA P&B - LP'!$A$1:$F$31,5,0) -> INACTIVO | F38: =VLOOKUP($D38,'ESTRUCTURA P&B - LP'!$A$1:$F$31,6,0) -> INACTIVO | G38: MIRANDA | H38: =VLOOKUP(Tabla3[[#This Row],[NUEVA RUTA]],Tabla1[#All],2,0) -> INACTIVO | I38: =VLOOKUP($A38,Clientes!$A$1:$C$1999,3,0) -> AUT KLASSE | J38: 0 | K38: =VLOOKUP($J38,'ESTRUCTURA P&B - LP'!$A$1:$F$40,5,0) -> INACTIVO | L38: =IFERROR(VLOOKUP($J38,'[2]POTENCIAL X ZONA'!$B$4:$G$21,6,0),0) -> 0 | M38: =IFERROR(VLOOKUP($A38,'Convenio Clientes'!$D:$F,3,0),"SN CNV") -> 01 | N38: 06 | O38: 0 | P38: INACTIVO | Q38: NO | R38: =VLOOKUP($N38,Tabla2[#All],3,0) -> SUPERMERCADOS INDEPENDIENTES | S38: AAV SAN SEBASTIAN EDIF PLAZA'S | T38: PISO PB OF UNICA | U38: CARACAS
A39: J306725024 | B39: AUTOMERCADOS PLAZA'S, C.A. | C39: 58 | D39: 10 | E39: =VLOOKUP($D39,'ESTRUCTURA P&B - LP'!$A$1:$F$31,5,0) -> MILAGROS FERNANDEZ 10 | F39: =VLOOKUP($D39,'ESTRUCTURA P&B - LP'!$A$1:$F$31,6,0) -> MILAGROS FERNANDEZ | G39: MIRANDA | H39: =VLOOKUP(Tabla3[[#This Row],[NUEVA RUTA]],Tabla1[#All],2,0) -> CAPITAL | I39: =VLOOKUP($A39,Clientes!$A$1:$C$1999,3,0) -> 42 PLAZA | J39: 10 | K39: =VLOOKUP($J39,'ESTRUCTURA P&B - LP'!$A$1:$F$40,5,0) -> MILAGROS FERNANDEZ 10 | L39: =IFERROR(VLOOKUP($J39,'[2]POTENCIAL X ZONA'!$B$4:$G$21,6,0),0) -> B | M39: =IFERROR(VLOOKUP($A39,'Convenio Clientes'!$D:$F,3,0),"SN CNV") -> 22 | N39: 03 | O39: 60 | P39: EVENTUAL | Q39: SI | R39: =VLOOKUP($N39,Tabla2[#All],3,0) -> CADENAS - SUPERMERCADOS | S39: AV LARA CRUCE CON CALLE BRANGER | T39: CC REGIONAL LOCAL SUPERMERCADO | U39: CARACAS
A40: J407238035 | B40: AUTOMERCADOS SUPER REY VALENCIA C,A | C40: 98 | D40: 98 | E40: =VLOOKUP($D40,'ESTRUCTURA P&B - LP'!$A$1:$F$31,5,0) -> INACTIVO | F40: =VLOOKUP($D40,'ESTRUCTURA P&B - LP'!$A$1:$F$31,6,0) -> INACTIVO | G40: CARABOBO | H40: =VLOOKUP(Tabla3[[#This Row],[NUEVA RUTA]],Tabla1[#All],2,0) -> INACTIVO | I40: =VLOOKUP($A40,Clientes!$A$1:$C$1999,3,0) -> AUTOM SUPER REY | J40: 12 | K40: =VLOOKUP($J40,'ESTRUCTURA P&B - LP'!$A$1:$F$40,5,0) -> JUAN LEÓN 12 | L40: =IFERROR(VLOOKUP($J40,'[2]POTENCIAL X ZONA'!$B$4:$G$21,6,0),0) -> P | M40: =IFERROR(VLOOKUP($A40,'Convenio Clientes'!$D:$F,3,0),"SN CNV") -> 01 | N40: 06 | O40: 15 | P40: INACTIVO | Q40: NO | R40: =VLOOKUP($N40,Tabla2[#All],3,0) -> SUPERMERCADOS INDEPENDIENTES | S40: CALLE SOUBLETTE C/C BOYACA CC 19 | T40: DE ABRIL N MZZ. SECTOR CENTRO | U40: VALENCIA
...

Sheet Convenio Clientes
B2: ASESOR | C2: GERENTE | D2: RIF | E2: NOMBRE DE CLEINTE | F2: CONVENIO
B3: =IFERROR(VLOOKUP($D3,'CLIENTES NUEVA ID ZONA'!$A:$F,5,0),"INACTIVO") -> ANDREINA RANGEL 21 | C3: =IFERROR(VLOOKUP($D3,'CLIENTES NUEVA ID ZONA'!$A:$F,6,0),"INACTIVO") -> ANDREINA RANGEL | D3: J403154490 | E3: FARMACIA FARMAESTRELLA, C.A | F3: 01
B4: =IFERROR(VLOOKUP($D4,'CLIENTES NUEVA ID ZONA'!$A:$F,5,0),"INACTIVO") -> ANDREINA RANGEL 21 | C4: =IFERROR(VLOOKUP($D4,'CLIENTES NUEVA ID ZONA'!$A:$F,6,0),"INACTIVO") -> ANDREINA RANGEL | D4: J409767205 | E4: DROGUERIA FARMACEUTICA 24, C.A | F4: 26
B5: =IFERROR(VLOOKUP($D5,'CLIENTES NUEVA ID ZONA'!$A:$F,5,0),"INACTIVO") -> ANDREINA RANGEL 21 | C5: =IFERROR(VLOOKUP($D5,'CLIENTES NUEVA ID ZONA'!$A:$F,6,0),"INACTIVO") -> ANDREINA RANGEL | D5: J070012250 | E5: C.A. MAFARTA | F5: 21
B6: =IFERROR(VLOOKUP($D6,'CLIENTES NUEVA ID ZONA'!$A:$F,5,0),"INACTIVO") -> ANDREINA RANGEL 21 | C6: =IFERROR(VLOOKUP($D6,'CLIENTES NUEVA ID ZONA'!$A:$F,6,0),"INACTIVO") -> ANDREINA RANGEL | D6: J070095008 | E6: DROGUERIA COBECA OCCIDENTE,C.A. | F6: 21 | I6: Leyenda
B7: =IFERROR(VLOOKUP($D7,'CLIENTES NUEVA ID ZONA'!$A:$F,5,0),"INACTIVO") -> ANDREINA RANGEL 21 | C7: =IFERROR(VLOOKUP($D7,'CLIENTES NUEVA ID ZONA'!$A:$F,6,0),"INACTIVO") -> ANDREINA RANGEL | D7: J070114606 | E7: FARMACIAS GALERIAS COMPRE CON MENOS,C.A. | F7: 01 | I7: Convenio | J7: Descripción
B8: =IFERROR(VLOOKUP($D8,'CLIENTES NUEVA ID ZONA'!$A:$F,5,0),"INACTIVO") -> ANDREINA RANGEL 21 | C8: =IFERROR(VLOOKUP($D8,'CLIENTES NUEVA ID ZONA'!$A:$F,6,0),"INACTIVO") -> ANDREINA RANGEL | D8: J075361776 | E8: DROGUERIA COBECA CENTRO C.A. | F8: 21 | I8: 01 | J8: Clientes General - Bolívares | K8: =COUNTIF($F$2:$F$1080,I8) -> 527
B9: =IFERROR(VLOOKUP($D9,'CLIENTES NUEVA ID ZONA'!$A:$F,5,0),"INACTIVO") -> ANDREINA RANGEL 21 | C9: =IFERROR(VLOOKUP($D9,'CLIENTES NUEVA ID ZONA'!$A:$F,6,0),"INACTIVO") -> ANDREINA RANGEL | D9: J298430958 | E9: FARMACIA COLSALUD C.A. | F9: 01 | I9: 21 | J9: Clientes General - Dólares | K9: =COUNTIF($F$2:$F$1080,I9) -> 239
B10: =IFERROR(VLOOKUP($D10,'CLIENTES NUEVA ID ZONA'!$A:$F,5,0),"INACTIVO") -> ANDREINA RANGEL 21 | C10: =IFERROR(VLOOKUP($D10,'CLIENTES NUEVA ID ZONA'!$A:$F,6,0),"INACTIVO") -> ANDREINA RANGEL | D10: J299310131 | E10: FARMACIA LAS RUBIO C.A. | F10: 01 | I10: 03 | J10: Desc 2% - Bolívares | K10: =COUNTIF($F$2:$F$1080,I10) -> 0
B11: =IFERROR(VLOOKUP($D11,'CLIENTES NUEVA ID ZONA'!$A:$F,5,0),"INACTIVO") -> ANDREINA RANGEL 21 | C11: =IFERROR(VLOOKUP($D11,'CLIENTES NUEVA ID ZONA'!$A:$F,6,0),"INACTIVO") -> ANDREINA RANGEL | D11: J300666204 | E11: DROGUERIA COBECA ORIENTE C.A. | F11: 21 | I11: 23 | J11: Desc 2% - Dólares | K11: =COUNTIF($F$2:$F$1080,I11) -> 1
B12: =IFERROR(VLOOKUP($D12,'CLIENTES NUEVA ID ZONA'!$A:$F,5,0),"INACTIVO") -> ANDREINA RANGEL 21 | C12: =IFERROR(VLOOKUP($D12,'CLIENTES NUEVA ID ZONA'!$A:$F,6,0),"INACTIVO") -> ANDREINA RANGEL | D12: J308620483 | E12: FARMACIA COVIDES, C.A. | F12: 01 | I12: 04 | J12: Desc 3% - Bolívares | K12: =COUNTIF($F$2:$F$1080,I12) -> 1
B13: =IFERROR(VLOOKUP($D13,'CLIENTES NUEVA ID ZONA'!$A:$F,5,0),"INACTIVO") -> ANDREINA RANGEL 21 | C13: =IFERROR(VLOOKUP($D13,'CLIENTES NUEVA ID ZONA'!$A:$F,6,0),"INACTIVO") -> ANDREINA RANGEL | D13: J311877053 | E13: DROGUERIA MEDICA DEL SUR C.A. | F13: 01 | I13: 24 | J13: Desc 3% - Dólares | K13: =COUNTIF($F$2:$F$1080,I13) -> 3
B14: =IFERROR(VLOOKUP($D14,'CLIENTES NUEVA ID ZONA'!$A:$F,5,0),"INACTIVO") -> ANDREINA RANGEL 21 | C14: =IFERROR(VLOOKUP($D14,'CLIENTES NUEVA ID ZONA'!$A:$F,6,0),"INACTIVO") -> ANDREINA RANGEL | D14: J314890638 | E14: DROGUERIA COL MEDICA, S.A. | F14: 01 | I14: 06 | J14: Desc 5% - Bolívares | K14: =COUNTIF($F$2:$F$1080,I14) -> 2
B15: =IFERROR(VLOOKUP($D15,'CLIENTES NUEVA ID ZONA'!$A:$F,5,0),"INACTIVO") -> ANDREINA RANGEL 21 | C15: =IFERROR(VLOOKUP($D15,'CLIENTES NUEVA ID ZONA'!$A:$F,6,0),"INACTIVO") -> ANDREINA RANGEL | D15: J405979062 | E15: DROGUERIA Y SUMINISTROS DROFARZUCA C.A | F15: 26 | I15: 26 | J15: Desc 5% - Dólares | K15: =COUNTIF($F$2:$F$1080,I15) -> 96
B16: =IFERROR(VLOOKUP($D16,'CLIENTES NUEVA ID ZONA'!$A:$F,5,0),"INACTIVO") -> ANDREINA RANGEL 21 | C16: =IFERROR(VLOOKUP($D16,'CLIENTES NUEVA ID ZONA'!$A:$F,6,0),"INACTIVO") -> ANDREINA RANGEL | D16: J406823570 | E16: FARMACIA FARMA SERVICIO MARACAIBO, C.A | F16: 01 | I16: 10 | J16: Desc 10% - Bolívares | K16: =COUNTIF($F$2:$F$1080,I16) -> 12
B17: =IFERROR(VLOOKUP($D17,'CLIENTES NUEVA ID ZONA'!$A:$F,5,0),"INACTIVO") -> ANDREINA RANGEL 21 | C17: =IFERROR(VLOOKUP($D17,'CLIENTES NUEVA ID ZONA'!$A:$F,6,0),"INACTIVO") -> ANDREINA RANGEL | D17: J406897205 | E17: DROGUERIA MEDICA ESPECIAL, C.A | F17: 01 | I17: 20 | J17: Desc 10% - Dólares | K17: =COUNTIF($F$2:$F$1080,I17) -> 105
B18: =IFERROR(VLOOKUP($D18,'CLIENTES NUEVA ID ZONA'!$A:$F,5,0),"INACTIVO") -> ANDREINA RANGEL 21 | C18: =IFERROR(VLOOKUP($D18,'CLIENTES NUEVA ID ZONA'!$A:$F,6,0),"INACTIVO") -> ANDREINA RANGEL | D18: J407332775 | E18: FARMACIA SUPERSALUD DEL ZULIA, C.A | F18: 01 | I18: 15 | J18: Ecommerce - Bolívares | K18: =COUNTIF($F$2:$F$1080,I18) -> 0
B19: =IFERROR(VLOOKUP($D19,'CLIENTES NUEVA ID ZONA'!$A:$F,5,0),"INACTIVO") -> ANDREINA RANGEL 21 | C19: =IFERROR(VLOOKUP($D19,'CLIENTES NUEVA ID ZONA'!$A:$F,6,0),"INACTIVO") -> ANDREINA RANGEL | D19: J409182002 | E19: FARMACIA FARMAEXPRESS 24 LA 72, CA | F19: 01 | I19: 50 | J19: Ecommerce - Dólares | K19: =COUNTIF($F$2:$F$1080,I19) -> 75
... B21: =IFERROR(VLOOKUP($D21,'CLIENTES NUEVA ID ZONA'!$A:$F,5,0),"INACTIVO") -> ANDREINA RANGEL 21 | C21: =IFERROR(VLOOKUP($D21,'CLIENTES NUEVA ID ZONA'!$A:$F,6,0),"INACTIVO") -> ANDREINA RANGEL | D21: J500325371 | E21: FARMACIA FARMAEXPRESS 24 SAN FRANCISCO, C.A. | F21: 21 | I21: 22 | J21: Mas 5% del canal 21 - Dólares | K21: =COUNTIF($F$2:$F$1080,I21) -> 12
B22: =IFERROR(VLOOKUP($D22,'CLIENTES NUEVA ID ZONA'!$A:$F,5,0),"INACTIVO") -> ANDREINA RANGEL 21 | C22: =IFERROR(VLOOKUP($D22,'CLIENTES NUEVA ID ZONA'!$A:$F,6,0),"INACTIVO") -> ANDREINA RANGEL | D22: J298069783 | E22: FARMACIA LA LAGO,C.A. | F22: 21
B23: =IFERROR(VLOOKUP($D23,'CLIENTES NUEVA ID ZONA'!$A:$F,5,0),"INACTIVO") -> ANDREINA RANGEL 21 | C23: =IFERROR(VLOOKUP($D23,'CLIENTES NUEVA ID ZONA'!$A:$F,6,0),"INACTIVO") -> ANDREINA RANGEL | D23: J400145171 | E23: FARMACIA TIERRA NEGRA, C.A. | F23: 21
B24: =IFERROR(VLOOKUP($D24,'CLIENTES NUEVA ID ZONA'!$A:$F,5,0),"INACTIVO") -> ANDREINA RANGEL 21 | C24: =IFERROR(VLOOKUP($D24,'CLIENTES NUEVA ID ZONA'!$A:$F,6,0),"INACTIVO") -> ANDREINA RANGEL | D24: J411801313 | E24: FARMACIA AVENIDA UNIVERSIDAD, CA | F24: 21
B25: =IFERROR(VLOOKUP($D25,'CLIENTES NUEVA ID ZONA'!$A:$F,5,0),"INACTIVO") -> ANDREINA RANGEL 21 | C25: =IFERROR(VLOOKUP($D25,'CLIENTES NUEVA ID ZONA'!$A:$F,6,0),"INACTIVO") -> ANDREINA RANGEL | D25: J500029780 | E25: DROGUERIA DROPLUS OCCIDENTE, C.A | F25: 26
B26: =IFERROR(VLOOKUP($D26,'CLIENTES NUEVA ID ZONA'!$A:$F,5,0),"INACTIVO") -> JOSEPH PADILLA 61 | C26: =IFERROR(VLOOKUP($D26,'CLIENTES NUEVA ID ZONA'!$A:$F,6,0),"INACTIVO") -> ANDREINA RANGEL | D26: J312256761 | E26: DROGUERIA EL BIENESTAR DROBIENCA, C.A. | F26: 26
B27: =IFERROR(VLOOKUP($D27,'CLIENTES NUEVA ID ZONA'!$A:$F,5,0),"INACTIVO") -> ANDREINA RANGEL 21 | C27: =IFERROR(VLOOKUP($D27,'CLIENTES NUEVA ID ZONA'!$A:$F,6,0),"INACTIVO") -> ANDREINA RANGEL | D27: J500925115 | E27: DROGUERIA EDA, C.A | F27: 26
B28: =IFERROR(VLOOKUP($D28,'CLIENTES NUEVA ID ZONA'!$A:$F,5,0),"INACTIVO") -> ANDREINA RANGEL 21 | C28: =IFERROR(VLOOKUP($D28,'CLIENTES NUEVA ID ZONA'!$A:$F,6,0),"INACTIVO") -> ANDREINA RANGEL | D28: J408567709 | E28: DROGUERIA DROMARKO, C.A | F28: 26
B29: =IFERROR(VLOOKUP($D29,'CLIENTES NUEVA ID ZONA'!$A:$F,5,0),"INACTIVO") -> ANDREINA RANGEL 21 | C29: =IFERROR(VLOOKUP($D29,'CLIENTES NUEVA ID ZONA'!$A:$F,6,0),"INACTIVO") -> ANDREINA RANGEL | D29: J501933669 | E29: DROGUERIA 365, C.A | F29: 26
B30: =IFERROR(VLOOKUP($D30,'CLIENTES NUEVA ID ZONA'!$A:$F,5,0),"INACTIVO") -> JOSEPH PADILLA 61 | C30: =IFERROR(VLOOKUP($D30,'CLIENTES NUEVA ID ZONA'!$A:$F,6,0),"INACTIVO") -> ANDREINA RANGEL | D30: J303525938 | E30: H.A ESPOSITO, C.A | F30: 20
B31: =IFERROR(VLOOKUP($D31,'CLIENTES NUEVA ID ZONA'!$A:$F,5,0),"INACTIVO") -> ANDREINA RANGEL 62 | C31: =IFERROR(VLOOKUP($D31,'CLIENTES NUEVA ID ZONA'!$A:$F,6,0),"INACTIVO") -> ANDREINA RANGEL | D31: J305479925 | E31: DISTRIBUCIONES VERA, C.A. | F31: 21
B32: =IFERROR(VLOOKUP($D32,'CLIENTES NUEVA ID ZONA'!$A:$F,5,0),"INACTIVO") -> ANDREINA RANGEL 62 | C32: =IFERROR(VLOOKUP($D32,'CLIENTES NUEVA ID ZONA'!$A:$F,6,0),"INACTIVO") -> ANDREINA RANGEL | D32: J308460281 | E32: CREA - DESARROLLOS, SOCIEDAD ANONIMA (CREDESA) | F32: 21
B33: =IFERROR(VLOOKUP($D33,'CLIENTES NUEVA ID ZONA'!$A:$F,5,0),"INACTIVO") -> ANDREINA RANGEL 62 | C33: =IFERROR(VLOOKUP($D33,'CLIENTES NUEVA ID ZONA'!$A:$F,6,0),"INACTIVO") -> ANDREINA RANGEL | D33: J403830339 | E33: MARKET DISTRIBUICIONES,C.A | F33: 20
... B198: =IFERROR(VLOOKUP($D198,'CLIENTES NUEVA ID ZONA'!$A:$F,5,0),"INACTIVO") -> EDUWARD MARTÍNEZ | C198: =IFERROR(VLOOKUP($D198,'CLIENTES NUEVA ID ZONA'!$A:$F,6,0),"INACTIVO") -> MILAGROS FERNANDEZ | D198: J307494166 | E198: FARMACIA LOCPAR 18, C.A. | F198: 21
B199: =IFERROR(VLOOKUP($D199,'CLIENTES NUEVA ID ZONA'!$A:$F,5,0),"INACTIVO") -> ELVIS RONDON | C199: =IFERROR(VLOOKUP($D199,'CLIENTES NUEVA ID ZONA'!$A:$F,6,0),"INACTIVO") -> MILAGROS FERNANDEZ | D199: J307976420 | E199: FARMACIA NORAM, C.A. | F199: 21
B200: =IFERROR(VLOOKUP($D200,'CLIENTES NUEVA ID ZONA'!$A:$F,5,0),"INACTIVO") -> ELVIS RONDON | C200: =IFERROR(VLOOKUP($D200,'CLIENTES NUEVA ID ZONA'!$A:$F,6,0),"INACTIVO") -> MILAGROS FERNANDEZ | D200: J311583939 | E200: FARMACIA 9 ENE, C.A. | F200: 21
B201: =IFERROR(VLOOKUP($D201,'CLIENTES NUEVA ID ZONA'!$A:$F,5,0),"INACTIVO") -> INACTIVO | C201: =IFERROR(VLOOKUP($D201,'CLIENTES NUEVA ID ZONA'!$A:$F,6,0),"INACTIVO") -> INACTIVO | D201: J311609946 | E201: FARMACIA SALUD GUAYCAR C.A. | F201: 01
B202: =IFERROR(VLOOKUP($D202,'CLIENTES NUEVA ID ZONA'!$A:$F,5,0),"INACTIVO") -> EDUWARD MARTÍNEZ | C202: =IFERROR(VLOOKUP($D202,'CLIENTES NUEVA ID ZONA'!$A:$F,6,0),"INACTIVO") -> MILAGROS FERNANDEZ | D202: J502022120 | E202: FARMACIA LCT 18, C.A | F202: 21
B203: =IFERROR(VLOOKUP($D203,'CLIENTES NUEVA ID ZONA'!$A:$F,5,0),"INACTIVO") -> EVENTUALES | C203: =IFERROR(VLOOKUP($D203,'CLIENTES NUEVA ID ZONA'!$A:$F,6,0),"INACTIVO") -> ROSLI APONTE | D203: J300706206 | E203: INDUSTRIAS CORPAÑAL, C.A. | F203: 01
B204: =IFERROR(VLOOKUP($D204,'CLIENTES NUEVA ID ZONA'!$A:$F,5,0),"INACTIVO") -> EVENTUALES | C204: =IFERROR(VLOOKUP($D204,'CLIENTES NUEVA ID ZONA'!$A:$F,6,0),"INACTIVO") -> ROSLI APONTE | D204: J308487406 | E204: ASOC CIVIL INSTITUTO DE TEOLOGIA PARA RELIGIOSOS | F204: 21
B205: =IFERROR(VLOOKUP($D205,'CLIENTES NUEVA ID ZONA'!$A:$F,5,0),"INACTIVO") -> DUBRASKA PÉREZ 11 | C205: =IFERROR(VLOOKUP($D205,'CLIENTES NUEVA ID ZONA'!$A:$F,6,0),"INACTIVO") -> DUBRASKA PÉREZ | D205: J313650153 | E205: CONFECCIONES Y DISTRIBUIDORA P.H.E.S. C.A. | F205: 01
B206: =IFERROR(VLOOKUP($D206,'CLIENTES NUEVA ID ZONA'!$A:$F,5,0),"INACTIVO") -> EVENTUALES | C206: =IFERROR(VLOOKUP($D206,'CLIENTES NUEVA ID ZONA'!$A:$F,6,0),"INACTIVO") -> ROSLI APONTE | D206: J002416262 | E206: CONDOMINIO RES. EL NARANJAL TORRE D (X) | F206: 21
...

Sheet Sucursales
B2: Código de dirección | C2: Número de cliente | D2: Nombre de cliente | E2: Nombre corto | F2: RUTA | G2: VENDEDOR | H2: GERENTE | I2: SUCURSAL
B3: 10018 | C3: J000797218 | D3: INVERSIONES LUVEBRAS, C.A. | E3: 91 LUVEBRAS | F3: 57 | G3: CARLOS ZURITA | H3: MILAGROS FERNANDEZ | I3: GUATIRE (VALLE ARRIB)
B4: 10019 | C4: J000797218 | D4: INVERSIONES LUVEBRAS, C.A. | E4: 91 LUVEBRAS | F4: 57 | G4: CARLOS ZURITA | H4: MILAGROS FERNANDEZ | I4: GUATIRE (ESMERALDA )
B5: 10020 | C5: J000797218 | D5: INVERSIONES LUVEBRAS, C.A. | E5: 91 LUVEBRAS | F5: 57 | G5: CARLOS ZURITA | H5: MILAGROS FERNANDEZ | I5: LA CASTELLANA
B6: 10021 | C6: J000797218 | D6: INVERSIONES LUVEBRAS, C.A. | E6: 91 LUVEBRAS | F6: 58 | G6: ELVIS RONDON | H6: MILAGROS FERNANDEZ | I6: EL MARQUÉS
B7: 10022 | C7: J000797218 | D7: INVERSIONES LUVEBRAS, C.A. | E7: 91 LUVEBRAS | F7: 58 | G7: ELVIS RONDON | H7: MILAGROS FERNANDEZ | I7: LA FLORIDA
B8: 10023 | C8: J000797218 | D8: INVERSIONES LUVEBRAS, C.A. | E8: 91 LUVEBRAS | F8: 58 | G8: ELVIS RONDON | H8: MILAGROS FERNANDEZ | I8: SANTA MÓNICA
B9: 10024 | C9: J000797218 | D9: INVERSIONES LUVEBRAS, C.A. | E9: 91 LUVEBRAS | F9: 58 | G9: ELVIS RONDON | H9: MILAGROS FERNANDEZ | I9: SANTA INES
B10: 50002 | C10: J000811601 | D10: AUTOMERCADO LUZ C.A. | E10: AUTOMERCADO LUZ | F10: 58 | G10: VACANTE | H10: MILAGROS FERNANDEZ | I10: CHACAO
B11: 50019 | C11: J000811601 | D11: AUTOMERCADO LUZ C.A. | E11: AUTOMERCADO LUZ | F11: 58 | G11: VACANTE | H11: MILAGROS FERNANDEZ | I11: LA FLORIDA (ANDRÉS BELLO)
B12: 11043 | C12: J305065616 | D12: PLANSUAREZ, C.A. | E12: 55 PLANSUAREZ | F12: 57 | G12: CARLOS ZURITA | H12: MILAGROS FERNANDEZ | I12: CAURIMARE
B13: 11044 | C13: J305065616 | D13: PLANSUAREZ, C.A. | E13: 55 PLANSUAREZ | F13: 57 | G13: CARLOS ZURITA | H13: MILAGROS FERNANDEZ | I13: LA URBINA
B14: 11045 | C14: J305065616 | D14: PLANSUAREZ, C.A. | E14: 55 PLANSUAREZ | F14: 57 | G14: CARLOS ZURITA | H14: MILAGROS FERNANDEZ | I14: LA TRINIDAD
... B55: 10110 | C55: J413273071 | D55: HIPER LIDER CERRO VERDE, C.A | E55: 90 SUPER LIDER | F55: 12 | G55: JUAN LEON | H55: DUBRASKA PÉREZ | I55: CUA
B56: 10092 | C56: J500199759 | D56: FORUM SUPER MAYORISTA, C.A | E56: FORUM | F56: 10 | I56: LOS PROCERES -IPFA
B57: 10098 | C57: J500199759 | D57: FORUM SUPER MAYORISTA, C.A | E57: FORUM | F57: 10 | I57: GUARENAS
B58: 10099 | C58: J500199759 | D58: FORUM SUPER MAYORISTA, C.A | E58: FORUM | F58: 10 | I58: VALENCIA
B59: 10100 | C59: J500199759 | D59: FORUM SUPER MAYORISTA, C.A | E59: FORUM | F59: 10 | I59: PORTUGUESA
B60: 10103 | C60: J500199759 | D60: FORUM SUPER MAYORISTA, C.A | E60: FORUM | F60: 10 | I60: MATURIN
B61: 10104 | C61: J500199759 | D61: FORUM SUPER MAYORISTA, C.A | E61: FORUM | F61: 10 | I61: CENDIS - CUA
B62: 10105 | C62: J500199759 | D62: FORUM SUPER MAYORISTA, C.A | E62: FORUM | F62: 10 | I62: PARAISO
B63: 10106 | C63: J500199759 | D63: FORUM SUPER MAYORISTA, C.A | E63: FORUM | F63: 10 | I63: CARRIZAL
B64: 50078 | C64: J500199759 | D64: FORUM SUPER MAYORISTA, C.A | E64: FORUM | F64: 10 | I64: CAGUA
B65: 10108 | C65: J500199759 | D65: FORUM SUPER MAYORISTA, C.A | E65: FORUM | F65: 10 | I65: GUATIRE
B66: 10107 | C66: J500199759 | D66: FORUM SUPER MAYORISTA, C.A | E66: FORUM | F66: 10 | I66: LA URBINA - CARACAS
B67: 10111 | C67: J500199759 | D67: FORUM SUPER MAYORISTA, C.A | E67: FORUM | F67: 10 | I67: MARACAY
B68: 10118 | C68: J500199759 | D68: FORUM SUPER MAYORISTA, C.A | E68: FORUM | F68: 10 | I68: BARUTA - LA PIRAMIDE
B69: 23042 | C69: J411399655 | D69: GRAN ABASTO GIRASOL C.A | E69: ABASTO GIRASOL | F69: 23 | G69: MARTHA VILORIA | H69: DUBRASKA PÉREZ | I69: ACARIGUA-PORTUGUESA
B70: 23043 | C70: J411399655 | D70: GRAN ABASTO GIRASOL C.A | E70: ABASTO GIRASOL | F70: 23 | G70: MARTHA VILORIA | H70: DUBRASKA PÉREZ | I70: ARAURE-PORTUGUESA
B71: 23044 | C71: J411399655 | D71: GRAN ABASTO GIRASOL C.A | E71: ABASTO GIRASOL | F71: 23 | G71: MARTHA VILORIA | H71: DUBRASKA PÉREZ | I71: GUANARE-PORTUGUESA
B72: 23045 | C72: J411399655 | D72: GRAN ABASTO GIRASOL C.A | E72: ABASTO GIRASOL | F72: 23 | G72: MARTHA VILORIA | H72: DUBRASKA PÉREZ | I72: BARINAS
B73: 23062 | C73: J411399655 | D73: GRAN ABASTO GIRASOL C.A | E73: ABASTO GIRASOL | F73: 23 | G73: MARTHA VILORIA | H73: DUBRASKA PÉREZ | I73: BARQUISIMETO
B74: 11082 | C74: J500374275 | D74: IMPORTADORA EL TIO AMMI I, C.A | E74: EL TIO AMMI | F74: 11 | G74: DUBRASKA PÉREZ 11 | H74: DUBRASKA PÉREZ | I74: KAPITANIA - EL RECREO
B75: 11083 | C75: J500374275 | D75: IMPORTADORA EL TIO AMMI I, C.A | E75: EL TIO AMMI | F75: 11 | G75: DUBRASKA PÉREZ 11 | H75: DUBRASKA PÉREZ | I75: CAGUA
B76: 11084 | C76: J500374275 | D76: IMPORTADORA EL TIO AMMI I, C.A | E76: EL TIO AMMI | F76: 11 | G76: DUBRASKA PÉREZ 11 | H76: DUBRASKA PÉREZ | I76: VALENCIA
B77: 11085 | C77: J500374275 | D77: IMPORTADORA EL TIO AMMI I, C.A | E77: EL TIO AMMI | F77: 11 | G77: DUBRASKA PÉREZ 11 | H77: DUBRASKA PÉREZ | I77: GUACARA
B78: 11090 | C78: J500374461 | D78: IMPORTADORA EL TIO AMMI II, C.A | E78: EL TIO AMMI | F78: 11 | G78: DUBRASKA PÉREZ 11 | H78: DUBRASKA PÉREZ | I78: CRUZ VERDE
B79: 11091 | C79: J500374461 | D79: IMPORTADORA EL TIO AMMI II, C.A | E79: EL TIO AMMI | F79: 11 | G79: DUBRASKA PÉREZ 11 | H79: DUBRASKA PÉREZ | I79: CATIA
B80: 11092 | C80: J500374461 | D80: IMPORTADORA EL TIO AMMI II, C.A | E80: EL TIO AMMI | F80: 11 | G80: DUBRASKA PÉREZ 11 | H80: DUBRASKA PÉREZ | I80: CABIMAS
... B88: 11089 | C88: J500374518 | D88: IMPORTADORA EL TIO AMMI IV, C.A | E88: EL TIO AMMI | F88: 11 | G88: DUBRASKA PÉREZ 11 | H88: DUBRASKA PÉREZ | I88: MATURIN
...

Sheet SKU
A1: Número de artículo | B1: Descripción artículo | C1: MARCA | D1: ORIGEN | E1: FAMILIA | F1: U de M | G1: SUB - MARCA | H1: COMPAÑÍA | I1: ESTATUS | J1: PROVEEDOR | K1: EAN13 | L1: NOMBRE CORTO | M1: Contenido | N1: Peso | O1: Empaque
A2: 1010110021 | B2: DENCORUB CREMA 20X48 (E) | C2: DENCORUB | D2: PROPIA | E2: FARMA | F2: 48 | G2: DENCORUB | H2: LP | I2: INACTIVO | J2: LABORATORIOS PONCE | L2: DENCORUB CREMA 20GR | M2: 20 | N2: gr | O2: 48 | P2: =+A2 -> 1010110021
A3: 1010110041 | B3: DENCORUB CREMA 40X48 (E) | C3: DENCORUB | D3: PROPIA | E3: FARMA | F3: 48 | G3: DENCORUB | H3: LP | I3: INACTIVO | J3: LABORATORIOS PONCE | L3: DENCORUB CREMA 40GR | M3: 40 | N3: gr | O3: 48 | P3: =+A3 -> 1010110041
A4: 1010110081 | B4: DENCORUB CREMA 80X48 (E) | C4: DENCORUB | D4: PROPIA | E4: FARMA | F4: 48 | G4: DENCORUB | H4: LP | I4: INACTIVO | J4: LABORATORIOS PONCE | L4: DENCORUB CREMA 80GR | M4: 80 | N4: gr | O4: 48 | P4: =+A4 -> 1010110081
A5: 1010210041 | B5: DENCORUB GEL 40X48 (E) | C5: DENCORUB | D5: PROPIA | E5: FARMA | F5: 48 | G5: DENCORUB | H5: LP | I5: INACTIVO | J5: LABORATORIOS PONCE | L5: DENCORUB GEL 40GR | M5: 40 | N5: gr | O5: 48 | P5: =+A5 -> 1010210041
A6: 1010210081 | B6: DENCORUB GEL 80X48 (E) | C6: DENCORUB | D6: PROPIA | E6: FARMA | F6: 48 | G6: DENCORUB | H6: LP | I6: INACTIVO | J6: LABORATORIOS PONCE | L6: DENCORUB GEL 80GR | M6: 80 | N6: gr | O6: 48 | P6: =+A6 -> 1010210081
A7: 1010310075 | B7: DENCORUB AIR 75X24 (E) | C7: DENCORUB | D7: PROPIA | E7: FARMA | F7: 24 | G7: DENCORUB | H7: LP | I7: INACTIVO | J7: LABORATORIOS PONCE | L7: DENCORUB AIR 75 | M7: 75 | N7: gr | O7: 24 | P7: =+A7 -> 1010310075
